Workbook

Sheet Обзор
B2: Премиальный Longevity Resort , Бенчмарк CapEx
B3: Оборудование, ПО, SPA, кухня и медицинская инфраструктура в четырёх регионах
B5: Дата выпуска | C5: 2026-05-03
B6: Покрытие по уровням | C6: Lanserhof/CLP (полная медицинская глубина) | SHA/Chenot (медицина-лайт) | Six Senses Place (велнес-плюс)
B7: Профиль объекта | C7: 80–100 номеров (модель использует середину диапазона , 90 номеров); премиальное люкс-позиционирование
B8: Регионы ценообразования | C8: Западная Европа (EUR) | Северная Америка (USD) | Азия (USD, с указанием страны) | Россия (RUB, оценка)
B9: Количество позиций | C9: 134 позиции в 16 категориях
B11: СОДЕРЖИМОЕ КНИГИ
B12: Обзор | C12: Эта страница , методология, определения уровней, цветовая легенда
B13: Реестр оборудования | C13: Все 134 позиции с брендом, ценами в четырёх регионах, привязкой к уровню, источником и достоверностью
B14: Сводка CapEx по уровням | C14: Свод по уровням, группам и регионам. Живые формулы , изменения в реестре или keys_count пересчитают итоги.
B15: Окупаемость и выручка | C15: Блоки окупаемости оборудования, цены процедур и пакетов, логика прироста ADR, диапазоны окупаемости
B16: Региональные факторы стоимости | C16: Санкции, таможня и НДС, параллельный импорт, отечественные альтернативы , детально по России
B17: Источники и методология | C17: Все цитируемые источники, оценка достоверности и рекомендованный путь верификации
B20: ОПРЕДЕЛЕНИЯ УРОВНЕЙ
B21: Уровень Six Senses Place (велнес-плюс) | C21: Велнес-плюс. Премиальное SPA, полноценная термальная зона, пилатес и тренажёрный зал, полная кухня, PMS и ИТ. Без медицинского центра, визуализации, собственной лаборатории и МИС. Позиции этого уровня входят во ВСЕ уровни (операционная база).
B22: Уровень SHA/Chenot (медицина-лайт) | C22: Медицина-лайт. Добавляются УЗИ, DEXA, рентген, базовые лабораторные анализаторы, ЭКГ-комплекс, HSAT, кресла для капельниц, FibroScan, RMR, МИС среднего класса и базовая медицинская инфраструктура.
B23: Уровень Lanserhof/CLP (полный медицинский) | C23: Полная медицинская глубина. Добавляются МРТ 3 Тл и 1,5 Тл, КТ, ОКТ, маммография, полноценная PSG/ЭЭГ, озон/ИГГТ/HBOT, эстетические лазеры, полнофункциональный PACS, полная система медицинских газов, генератор и HEPA.
B24: Опциональный апселл | C24: Учитывается отдельно , Epic EHR, криолиполиз, парк ECG-патчей, корпоративные WHOOP/Garmin. НЕ входят в базовые итоги уровней.
B27: ЦВЕТОВАЯ ЛЕГЕНДА
B28: Жёсткий ввод | C28: Числа, которые пользователь меняет под сценарии (цены, keys_count, курсы)
B29: Формула / расчёт | C29: Ячейки, рассчитываемые книгой по введённым параметрам
B30: Кросс-листовая ссылка | C30: Ссылки на другие листы , поддерживают синхронность сводок с реестром
B31: Цвета достоверности | C31: Зелёный , высокая, жёлтый , средняя, оранжевый , низкая. Применяются к колонке достоверности в реестре.
B33: КАК ЧИТАТЬ ЭТУ КНИГУ
C34: 1. Реестр оборудования , единый источник истины. Изменение цены или количества там автоматически обновляет сводку CapEx через SUMPRODUCT.
C35: 2. Сводка CapEx использует логику включения уровней: позиции Six Senses учитываются во ВСЕХ трёх уровнях; позиции SHA , в CLP и SHA; позиции CLP , только в CLP.
C36: 3. Для ПО раздельно показаны единовременный CapEx и годовая подписка. Годовые суммы относятся к OpEx и в итоги CapEx не включаются.
C37: 4. Колонка России (₽) имеет НАИМЕНЬШУЮ достоверность , рекомендации по верификации см. в листе «Источники и методология».
C38: 5. «CapEx на номер» использует keys_count из ячейки B3 листа «Сводка CapEx по уровням» (по умолчанию 90 , редактируется).

Sheet Реестр оборудования
A1: ID | B1: Категория | C1: Подкатегория | D1: Оборудование | E1: Примеры брендов | F1: Назначение | G1: Уровень (скорректированный) | H1: Уровень (по исследованию) | I1: Цена , Западная Европа (€) | J1: Цена , Северная Америка (USD) | K1: Цена , Азия (USD) | L1: Страна Азии | M1: Цена , Россия, оценка (₽) | N1: Количество (80–100 номеров) | O1: Срок службы (лет) | P1: Годовое обслуживание (% CapEx) | Q1: FTE на эксплуатацию | R1: Источник | S1: Достоверность | T1: Дата проверки | U1: Примечания | V1: ЕС: годовая €, ПО | W1: СА: годовая $, ПО | X1: Азия: годовая $, ПО | Y1: Россия: годовая ₽, ПО | Z1: Путь(и) активации | AA1: Evidence (A/B/C) | AB1: Гормезис стек (Да/Нет)
A2: 1 | B2: Эстетика и регенеративные процедуры | C2: Аблятивно-неаблятивная платформа | D2: Модульная эстетическая лазерная платформа (BBL+Halo+ProFractional) | E2: Sciton JOULE X / Lumenis M22 | F2: Шлифовка кожи, удаление пигментации и сосудистых образований , рабочая лошадка эстетического направления. | G2: Уровень Lanserhof/CLP (полный медицинский) | H2: Уровень Lanserhof/CLP (полный медицинский) | I2: 180000 | J2: 215000 | K2: 175000 | L2: ОАЭ | M2: 25000000 | N2: 1 | O2: 8 | P2: 0.1 | Q2: 0.6 | R2: Дилерские предложения Sciton; платформа mJOULE с пробегом по цене $149 950 (mrp.io); прайсы Lumenis 2024. | S2: Средняя | T2: 2026-05 | U2: Регуляторное замечание: производитель , США. Импорт в Россию идёт по параллельным каналам с надбавкой 20–30%. Целесообразно рассмотреть европейские альтернативы (Asclepion, Quantel). | Z2: Диагностика | AA2: B | AB2: Нет
A3: 2 | B3: Эстетика и регенеративные процедуры | C3: Криолиполиз | D3: Система криолиполиза (редукция жировой ткани) | E3: Allergan CoolSculpting Elite / Cooltech Define | F3: Неинвазивная редукция жировой ткани , высокомаржинальная эстетическая услуга. | G3: Опциональный апселл | H3: Опциональный апселл | I3: 100000 | J3: 120000 | K3: 95000 | L3: ОАЭ | M3: 14000000 | N3: 1 | O3: 7 | P3: 0.1 | Q3: 0.4 | R3: Дилер Allergan, 2024; восстановленные системы CoolSculpting Elite на Offer Aesthetic. | S3: Средняя | T3: 2026-05 | U3: Регуляторное замечание: Allergan/AbbVie находятся под американским контролем. Для России предпочтительнее Cooltech (Испания, ныне Cocoon Medical). | Z3: Диагностика | AA3: B | AB3: Нет
A4: 3 | B4: Эстетика и регенеративные процедуры | C4: EMSculpt / электромагнитная стимуляция мышц | D4: Электромагнитная стимуляция мышц (HIFEM) | E4: BTL EMSculpt NEO | F4: Прирост мышечной массы и редукция жира , востребованная SPA-надстройка. | G4: Уровень Lanserhof/CLP (полный медицинский) | H4: Уровень SHA/Chenot (медицина-лайт) | I4: 130000 | J4: 150000 | K4: 125000 | L4: ОАЭ | M4: 18000000 | N4: 1 | O4: 7 | P4: 0.1 | Q4: 0.4 | R4: Дилерские предложения BTL Industries 2024–2025. | S4: Средняя | T4: 2026-05 | U4: Производитель BTL , чешская компания, поэтому канал поставки в Россию относительно чистый. | Z4: Диагностика | AA4: A | AB4: Нет
A5: 4 | B5: Эстетика и регенеративные процедуры | C5: HIFU-лифтинг кожи | D5: Микрофокусированный ультразвук для лифтинга кожи (HIFU) | E5: Merz Ultherapy Prime / Ulthera | F5: Безоперационное подтягивание кожи , востребованная процедура. | G5: Уровень SHA/Chenot (медицина-лайт) | H5: Уровень SHA/Chenot (медицина-лайт) | I5: 65000 | J5: 75000 | K5: 60000 | L5: ОАЭ | M5: 9000000 | N5: 1 | O5: 7 | P5: 0.12 | Q5: 0.4 | R5: Konmison: справочник цен на аппараты Ultherapy 2025; vsquareclinic об Ulthera Prime. | S5: Средняя | T5: 2026-05 | U5: Расходные картриджи , около $300 за процедуру. По России: производитель Merz базируется в ЕС, что снижает санкционные риски по сравнению с американскими аналогами. | Z5: Диагностика | AA5: A | AB5: Нет
A6: 5 | B6: Эстетика и регенеративные процедуры | C6: Светотерапия LED | D6: LED-кушетка/панель для медицинской светотерапии | E6: NovoTHOR / Celluma PRO panels | F6: Фотобиомодуляция для кожи, восстановления и программ долголетия. | G6: Уровень SHA/Chenot (медицина-лайт) | H6: Уровень SHA/Chenot (медицина-лайт) | I6: 65000 | J6: 78000 | K6: 60000 | L6: ОАЭ | M6: 9000000 | N6: 1 | O6: 10 | P6: 0.04 | Q6: 0.2 | R6: Розничные цены NovoTHOR 2024 (~$70–90 тыс.); панели Celluma Pro $3–5 тыс. как альтернатива. | S6: Средняя | T6: 2026-05 | U6: Полнотельная кушетка NovoTHOR , фирменное оборудование премиальных клиник. | Z6: Диагностика | AA6: A | AB6: Нет
A7: 6 | B7: Эстетика и регенеративные процедуры | C7: Радиочастотная терапия | D7: Аппарат радиочастотной терапии (Tecar 448 кГц) | E7: Indiba Activ Elite NS / Indiba CT9 | F7: Регенерация тканей, восстановление, контурирование тела , двойное применение в реабилитации и эстетике. | G7: Уровень SHA/Chenot (медицина-лайт) | H7: Уровень SHA/Chenot (медицина-лайт) | I7: 35000 | J7: 42000 | K7: 33000 | L7: ОАЭ | M7: 4800000 | N7: 2 | O7: 8 | P7: 0.07 | Q7: 0.6 | R7: Референтные предложения дилеров Indiba; клинические тарифы NYDNRehab; листинги б/у на eBay около $55 тыс. | S7: Средняя | T7: 2026-05 | U7: Производитель из Испании, что обеспечивает более чистый канал поставки в Россию по сравнению с американскими лазерами. | Z7: Диагностика | AA7: B | AB7: Нет
A8: 7 | B8: Эстетика и регенеративные процедуры | C8: Платформа сосудисто-пигментных лазеров | D8: Многоволновая эстетическая лазерная платформа (KTP+Nd:YAG) | E8: Cutera Excel V+ / Candela GentleMax Pro | F8: Сосудистые образования, пигментация, ревитализация кожи. | G8: Уровень Lanserhof/CLP (полный медицинский) | H8: Уровень Lanserhof/CLP (полный медицинский) | I8: 90000 | J8: 105000 | K8: 85000 | L8: ОАЭ | M8: 12500000 | N8: 1 | O8: 8 | P8: 0.1 | Q8: 0.5 | R8: Листинги новых Cutera Excel V+ от The Laser Agent 2025; Bimedis , диапазон б/у $18 613–49 950. | S8: Средняя | T8: 2026-05 | U8: Регуляторное замечание: эстетические лазеры из США и Израиля сталкиваются с ограничениями импорта в Россию. Поставка идёт через реэкспорт из Турции/ОАЭ с надбавкой 15–25% и риском отсутствия гарантии. | Z8: Диагностика | AA8: C | AB8: Нет
A9: 8 | B9: Состав тела и функциональная диагностика | C9: Состав тела , воздушная плетизмография | D9: Воздушный плетизмограф BodPod GS-X | E9: Cosmed BodPod GS-X | F9: Эталонный двухкомпонентный анализ состава тела , отличие премиального уровня от InBody. | G9: Уровень Six Senses Place (велнес-плюс) | H9: Уровень Lanserhof/CLP (полный медицинский) | I9: 50000 | J9: 58000 | K9: 48000 | L9: ОАЭ | M9: 6600000 | N9: 1 | O9: 12 | P9: 0.05 | Q9: 0.2 | R9: Дилерские предложения Cosmed; MedicalExpo 2024. | S9: Средняя | T9: 2026-05 | U9: Используется в Lanserhof и CLP. Тяжёлый аппарат, требует выделенного помещения со стабильной температурой. | Z9: Диагностика | AA9: A | AB9: Нет
A10: 9 | B10: Состав тела и функциональная диагностика | C10: Состав тела , биоимпеданс | D10: Анализатор состава тела медицинского класса (BIA, мультичастотный) | E10: InBody 970 / Seca mBCA 555 (medical-grade) | F10: Сегментарный состав тела, ECW/ICW, фазовый угол , базовое обследование в программах долголетия. | G10: Уровень Six Senses Place (велнес-плюс) | H10: Уровень Lanserhof/CLP (полный медицинский) | I10: 28000 | J10: 32600 | K10: 26000 | L10: ОАЭ | M10: 3700000 | N10: 2 | O10: 8 | P10: 0.05 | Q10: 0.3 | R10: Прайс InBody USA 2025 ($32 605); базовая Seca mBCA Pro $9 599; листинг HaB Direct mBCA 555. | S10: Высокая | T10: 2026-05 | U10: InBody 970 , рабочий стандарт; Seca mBCA 555 , медицинского класса CE. По России: дистрибьюторы доступны в Москве, санкционных проблем нет. | Z10: Диагностика | AA10: A | AB10: Нет
A11: 10 | B11: Состав тела и функциональная диагностика | C11: Кардиопульмонология | D11: Метаболическая платформа VO2max / CPET | E11: Cosmed K5 / Cosmed Quark CPET / MGC Diagnostics | F11: VO2max и базальный метаболизм , ключевые показатели здорового долголетия. | G11: Уровень SHA/Chenot (медицина-лайт) | H11: Уровень Lanserhof/CLP (полный медицинский) | I11: 45000 | J11: 52000 | K11: 42000 | L11: ОАЭ | M11: 6000000 | N11: 1 | O11: 10 | P11: 0.08 | Q11: 0.4 | R11: Дилеры Cosmed 2024; листинги MedicalExpo. | S11: Средняя | T11: 2026-05 | U11: CPET выполняют и в Lanserhof, и в SHA. В комплекте , беговая дорожка либо велоэргометр. | Z11: Диагностика | AA11: A | AB11: Нет
A12: 11 | B12: Состав тела и функциональная диагностика | C12: DEXA-сканер | D12: DEXA-сканер для анализа состава тела и плотности костной ткани | E12: Hologic Horizon / GE Lunar iDXA | F12: Эталон оценки минеральной плотности костей и состава тела. | G12: Уровень SHA/Chenot (медицина-лайт) | H12: Уровень Lanserhof/CLP (полный медицинский) | I12: 95000 | J12: 115000 | K12: 90000 | L12: ОАЭ | M12: 13100000 | N12: 1 | O12: 12 | P12: 0.07 | Q12: 0.4 | R12: Дилерские прайсы Hologic/GE 2024. | S12: Средняя | T12: 2026-05 | U12: Возможно пересечение с медицинской визуализацией , следует контролировать, чтобы позиция учитывалась только один раз. | Z12: Диагностика | AA12: A | AB12: Нет
A13: 12 | B13: Состав тела и функциональная диагностика | C13: Анализ опорной реакции и походки | D13: Система силовых платформ (двойная, встраиваемая) | E13: AMTI BMS400600 / Bertec FP4060 | F13: Опорная реакция, баланс, кинетика походки. | G13: Уровень SHA/Chenot (медицина-лайт) | H13: Уровень Lanserhof/CLP (полный медицинский) | I13: 45000 | J13: 52000 | K13: 42000 | L13: ОАЭ | M13: 6000000 | N13: 1 | O13: 15 | P13: 0.04 | Q13: 0.2 | R13: Предложения дилеров AMTI; партнёрские цены Noraxon 2024. | S13: Средняя | T13: 2026-05 | U13: Пара платформ; для монтажа требуется заглубление в полу. Часто используется в связке с системами Vicon. | Z13: Диагностика | AA13: C | AB13: Нет
... A66: 65 | B66: ИТ, МИС, ПО для пациентов | C66: Контроль доступа и RFID-замки | D66: Электронные замки номеров и контроль доступа в служебных зонах | E66: Salto, Assa Abloy VingCard, dormakaba | F66: RFID/мобильные ключи на дверь; раздельные зоны для персонала. | G66: Уровень Six Senses Place (велнес-плюс) | H66: Уровень Lanserhof/CLP (полный медицинский) | I66: 165000 | J66: 200000 | K66: 130000 | L66: Китай | M66: 20500000 | N66: 1 | O66: 12 | P66: 0.04 | Q66: 0 | R66: Kompareit hotel access $1500–2500/дверь; 100 дверей плюс 30 служебных. | S66: Высокая | T66: 2026-05 | U66: Премиальная спецификация (BLE и мобильный ключ). По России: VingCard поставляется параллельным импортом с надбавкой 20–25%. | Z66: Гостевой опыт | AA66: C | AB66: Нет
A67: 66 | B67: ИТ, МИС, ПО для пациентов | C67: МИС/EHR | D67: МИС среднего класса (уровень Athenahealth) | E67: Athenahealth athenaOne, Tebra, ModMed; Russian: МИС МедОфис, qMS | F67: Ведение клинической документации медицинского центра; интеграция с лабораторией и визуализацией. | G67: Уровень SHA/Chenot (медицина-лайт) | H67: Уровень Lanserhof/CLP (полный медицинский) | I67: 180000 | J67: 220000 | K67: 150000 | L67: Сингапур | M67: 12000000 | N67: 1 | O67: 7 | P67: 0 | Q67: 0.5 | R67: Athenahealth $140 за специалиста в месяц плюс 4–8% от собранной выручки; внедрение $2–5 тыс. на специалиста; emrguides.com 2025. | S67: Средняя | T67: 2026-05 | U67: По России: 152-ФЗ о локализации данных блокирует западные облачные МИС. Российские qMS/МедОфис обходятся примерно на 50% дешевле, но требуют кастомной интеграции. | V67: 90000 | W67: 110000 | X67: 75000 | Y67: 6000000 | Z67: Гостевой опыт, Снижение воспаления | AA67: C | AB67: Нет
A68: 67 | B68: ИТ, МИС, ПО для пациентов | C68: МИС (опционально, уровень Epic) | D68: МИС корпоративного уровня (Epic/Cerner) | E68: Epic Hyperspace, Oracle Health (Cerner Millennium) | F68: Полнофункциональная МИС больничного класса для медцентра курорта. | G68: Опциональный апселл | H68: Опциональный апселл | I68: 1800000 | J68: 2200000 | K68: 1500000 | L68: Сингапур | M68: 0 | N68: 0 | O68: 10 | P68: 0 | Q68: 1 | R68: Tactionsoft 2025 ($500 тыс. – 10 млн); arkenea.com Cerner; Veterans Memorial Hospital $3,88 млн. | S68: Средняя | T68: 2026-05 | U68: Избыточно для отеля 80–100 номеров; уместно только при стационарной мощности. В России развёртывание невозможно. | V68: 350000 | W68: 420000 | X68: 300000 | Y68: 0 | Z68: Гостевой опыт | AA68: C | AB68: Нет
A69: 68 | B69: ИТ, МИС, ПО для пациентов | C69: Гостевой опыт / мобильное приложение | D69: Гостевое мобильное приложение и in-room планшеты | E69: Crave Interactive, SuitePad, Hudini, INTELITY | F69: Мобильный check-in, заказ в номер, бронирование процедур, контент. | G69: Уровень Six Senses Place (велнес-плюс) | H69: Уровень Lanserhof/CLP (полный медицинский) | I69: 90000 | J69: 110000 | K69: 75000 | L69: Сингапур | M69: 9500000 | N69: 1 | O69: 5 | P69: 0 | Q69: 0 | R69: Бенчмарки hospitality tech; планшет $600–1200 на номер плюс лицензия $25–40 на номер в месяц. | S69: Средняя | T69: 2026-05 | U69: Включает планшеты в номера, лицензии и интеграцию с PMS/SPA. | V69: 35000 | W69: 42000 | X69: 28000 | Y69: 2800000 | Z69: Гостевой опыт | AA69: C | AB69: Нет
A70: 69 | B70: ИТ, МИС, ПО для пациентов | C70: Платформа долголетия для пациентов | D70: Специализированная платформа долголетия для пациентов | E70: Function Health (B2B), Hone Health, Healthspan; alt: custom | F70: Отслеживание биомаркеров, личный кабинет, продольные результаты, ИИ-аналитика. | G70: Уровень Six Senses Place (велнес-плюс) | H70: Уровень Lanserhof/CLP (полный медицинский) | I70: 75000 | J70: 90000 | K70: 65000 | L70: Сингапур | M70: 8500000 | N70: 1 | O70: 5 | P70: 0 | Q70: 0.5 | R70: Function Health B2B (Equinox $249, Higginbotham $334 в год за участника); sacra.com. | S70: Низкая | T70: 2026-05 | U70: Годовой ARR , около 200–300 активных участников по $250–350 в год. По России: потребуется кастомная разработка либо изолированный инстанс. | V70: 60000 | W70: 72000 | X70: 55000 | Y70: 4000000 | Z70: Гормезис, Активация AMPK, Снижение воспаления | AA70: B | AB70: Да
A71: 70 | B71: ИТ, МИС, ПО для пациентов | C71: Сетевая инфраструктура | D71: Проводная и Wi-Fi 6/7 магистраль (корпоративный класс) | E71: Cisco Meraki, RUCKUS Networks, Aruba; Russian: Eltex, QTECH | F71: Гостевая и служебная сети с сегментированными VLAN, включая медицинский сегмент. | G71: Уровень Six Senses Place (велнес-плюс) | H71: Уровень Lanserhof/CLP (полный медицинский) | I71: 220000 | J71: 260000 | K71: 170000 | L71: Сингапур | M71: 28000000 | N71: 1 | O71: 8 | P71: 0.1 | Q71: 0 | R71: RUCKUS/Cisco hospitality vertical; ~€2–3 тыс. за установленную точку доступа, 80 точек плюс коммутация. | S71: Средняя | T71: 2026-05 | U71: По России: Cisco/Aruba под санкциями с 2022 года. Замена , Eltex/QTECH либо серый рынок. | Z71: Снижение воспаления | AA71: C | AB71: Нет
A72: 71 | B72: ИТ, МИС, ПО для пациентов | C72: PMS , отельная часть | D72: Облачная PMS (отель 80–100 номеров класса люкс) | E72: Mews Enterprise, Oracle Opera Cloud, Protel; Russian: Bnovo, Shelter, TravelLine | F72: Бронирование, гостевые счета, хаускипинг, channel manager, интеграция POS. | G72: Уровень Six Senses Place (велнес-плюс) | H72: Уровень Lanserhof/CLP (полный медицинский) | I72: 45000 | J72: 55000 | K72: 38000 | L72: Сингапур | M72: 2500000 | N72: 1 | O72: 7 | P72: 0 | Q72: 0 | R72: Mews Enterprise (hoteltechreport, roommaster); цена Mews EUR 300/мес. | S72: Средняя | T72: 2026-05 | U72: По России на 2026 год: Mews и Opera ушли после санкций 2022 года. Российские альтернативы (Shelter, Bnovo) обходятся на 40–50% дешевле, но уступают премиальным сценариям. | V72: 36000 | W72: 45000 | X72: 32000 | Y72: 1500000 | Z72: Гормезис, Активация AMPK, Митохондриальная функция, Снижение воспаления | AA72: B | AB72: Да
A73: 72 | B73: ИТ, МИС, ПО для пациентов | C73: Безопасность , видеонаблюдение | D73: IP-видеонаблюдение (40–60 камер плюс NVR) | E73: Avigilon, Axis, Hanwha; Russian: TRASSIR, Macroscop | F73: Периметр и служебные зоны. | G73: Уровень Six Senses Place (велнес-плюс) | H73: Уровень Lanserhof/CLP (полный медицинский) | I73: 75000 | J73: 90000 | K73: 55000 | L73: Китай | M73: 7800000 | N73: 1 | O73: 10 | P73: 0.05 | Q73: 0 | R73: Avigilon/Axis у дилеров; ~€1–1,5 тыс. за установленную камеру. | S73: Высокая | T73: 2026-05 | U73: По России: доминирует TRASSIR; цена выгоднее западных решений. | Z73: Гормезис, Активация AMPK, Митохондриальная функция, Снижение воспаления | AA73: A | AB73: Да
A74: 73 | B74: ИТ, МИС, ПО для пациентов | C74: Система записи в SPA и медицинском блоке | D74: Интегрированная система записи на SPA и процедуры | E74: Book4Time, Agilysys Spa, ResortSuite | F74: Расписание терапевтов, загрузка кабинетов, управление пакетами, ритейл. | G74: Уровень Six Senses Place (велнес-плюс) | H74: Уровень Lanserhof/CLP (полный медицинский) | I74: 55000 | J74: 68000 | K74: 45000 | L74: Сингапур | M74: 3500000 | N74: 1 | O74: 7 | P74: 0 | Q74: 0 | R74: Book4Time, Agilysys, ResortSuite , ориентировочные цены 2025. | S74: Средняя | T74: 2026-05 | U74: Критично для премиальных велнес-резортов; интегрируется с PMS и МИС. | V74: 28000 | W74: 35000 | X74: 22000 | Y74: 1500000 | Z74: Гормезис, Активация AMPK, Митохондриальная функция, Снижение воспаления | AA74: B | AB74: Да
A75: 74 | B75: ИТ, МИС, ПО для пациентов | C75: Телефония и IPTV | D75: VoIP-телефония и IPTV | E75: Mitel, Cisco; LG/Samsung Pro:Idiom IPTV | F75: Телефония в номерах, IPTV, телефония в служебных зонах. | G75: Уровень Six Senses Place (велнес-плюс) | H75: Уровень Lanserhof/CLP (полный медицинский) | I75: 95000 | J75: 115000 | K75: 75000 | L75: Китай | M75: 12500000 | N75: 1 | O75: 10 | P75: 0.06 | Q75: 0 | R75: Бенчмарк интеграторов hospitality AV/IT. | S75: Средняя | T75: 2026-05 | U75: Резорты среднего сегмента иногда отказываются от стационарной телефонии в пользу стриминга. | Z75: Гормезис, Активация AMPK, Митохондриальная функция, Снижение воспаления, Гостевой опыт | AA75: C | AB75: Да
A76: 75 | B76: Инфузионная терапия | C76: Гипербарическая оксигенация | D76: Гипербарическая кислородная камера , мягкая HBOT (1,3–1,5 ATA) | E76: OxyHealth Vitaeris 320, Hyperbaric Centrales OxyVita, Summit to Sea Dive | F76: Мягкокорпусная гипербарическая оксигенация для протоколов восстановления и долголетия. | G76: Уровень Lanserhof/CLP (полный медицинский) | H76: Уровень Lanserhof/CLP (полный медицинский) | I76: 35000 | J76: 40000 | K76: 28000 | L76: Китай | M76: 4800000 | N76: 2 | O76: 10 | P76: 0.05 | Q76: 0.5 | R76: Прайс OxyHealth Vitaeris 320 $20–35 тыс.; типовая мягкокорпусная HBOT €25–45 тыс. Жёсткие медицинские камеры (2,0+ ATA) дороже в 5–10 раз. | S76: Средняя | T76: 2026-05 | U76: Объём ограничен мягкокорпусной HBOT (упрощённая регуляторика, без сжатого кислорода). Жёсткие камеры , отдельная категория, не учтены. По России: отечественные камеры BLKS и OxyHealth , параллельным импортом. | Z76: Гормезис, Активация AMPK, Митохондриальная функция, Снижение воспаления | AA76: A | AB76: Да
A77: 76 | B77: Инфузионная терапия | C77: ИГГТ | D77: Аппарат интервальной гипоксической-гипероксической тренировки | E77: Cellgym Pro / Lounge, Hypoxico Everest Summit II, GO2Altitude Biomedtech | F77: Интервальная гипоксия-гипероксия , митохондриальный тренинг, протокол долголетия. | G77: Уровень Lanserhof/CLP (полный медицинский) | H77: Уровень Lanserhof/CLP (полный медицинский) | I77: 35000 | J77: 40000 | K77: 28000 | L77: Китай | M77: 4800000 | N77: 3 | O77: 8 | P77: 0.05 | Q77: 0.3 | R77: Cellgym у дилеров €30–45 тыс. за Pro/Lounge; цены дистрибьюторов Hypoxico; референсы установок Cellgym в Cocoon Medical Spa. | S77: Низкая | T77: 2026-05 | U77: Оценочно: публичная цена Cellgym отсутствует. Розничная сессия €50–80. Три аппарата покрывают 25–30 сеансов в день. По России: отечественная Bio-Nova MTI/IHT , альтернатива за €12–18 тыс. | Z77: Гормезис, Активация AMPK, Снижение воспаления | AA77: B | AB77: Да
A78: 77 | B78: Инфузионная терапия | C78: IV-зона | D78: Кресло-реклайнер для IV-капельниц | E78: Champion Manufacturing 56 series, Stance Healthcare Bari, Winco CareCliner | F78: Удобное кресло-реклайнер для капельниц, NAD+ и витаминотерапии. | G78: Уровень SHA/Chenot (медицина-лайт) | H78: Уровень Lanserhof/CLP (полный медицинский) | I78: 3500 | J78: 4000 | K78: 2500 | L78: Китай | M78: 480000 | N78: 6 | O78: 10 | P78: 0.04 | Q78: 0 | R78: Champion / Stance / Winco , клинические реклайнеры $2 500–5 000; типовые предложения дилеров €3 000–4 500. | S78: Высокая | T78: 2026-05 | U78: 6–8 кресел на резорт 80–100 номеров. По России: отечественный Med-Mos и поставки через Турцию одинаково жизнеспособны. | Z78: Гормезис, Снижение воспаления | AA78: C | AB78: Да
A79: 78 | B79: Инфузионная терапия | C79: Инфузионные насосы | D79: Умный инфузионный насос | E79: B.Braun Infusomat Space, Baxter Sigma Spectrum IQ, BD Alaris | F79: Умный инфузионный насос с DERS для витаминов, NAD+, хелатной терапии и пептидов. | G79: Уровень SHA/Chenot (медицина-лайт) | H79: Уровень Lanserhof/CLP (полный медицинский) | I79: 3500 | J79: 4000 | K79: 2500 | L79: Китай | M79: 480000 | N79: 8 | O79: 7 | P79: 0.06 | Q79: 0 | R79: Outfront Medical / Coast Biomed Baxter Sigma Spectrum , восстановленные $1,5–2,5 тыс.; B.Braun , новый ~€3–4 тыс. | S79: Высокая | T79: 2026-05 | U79: 8 насосов на 6 кресел плюс 2 резервных. По России: B.Braun (Германия) поставляется, но сроки увеличены; используются и российские насосы Yelatma. | Z79: Митохондриальная функция, Очищение от стареющих клеток, Гормезис | AA79: B | AB79: Нет
A80: 79 | B80: Инфузионная терапия | C80: Озонотерапия | D80: Медицинский озонотерапевтический генератор | E80: Herrmann Apparatebau Hyper Medozon comfort, Zotzmann + Stahl OzonoSan, Humares Medozon | F80: Большая и малая аутогемотерапия, инсуффляция, озонированный физраствор. | G80: Уровень Lanserhof/CLP (полный медицинский) | H80: Уровень Lanserhof/CLP (полный медицинский) | I80: 18000 | J80: 0 | K80: 14000 | L80: Китай | M80: 2500000 | N80: 2 | O80: 10 | P80: 0.05 | Q80: 0.3 | R80: MedicalExpo Herrmann Hyper Medozon comfort; листинг HealthManagement.org; восстановленные на Medbidding €6–9 тыс.; новые €15–22 тыс. от немецких дилеров. | S80: Средняя | T80: 2026-05 | U80: Жёстко регулируется: запрещено/ограничено в США (FDA), разрешено в Германии, Австрии, Швейцарии, Испании, России под медицинским контролем. По России: озонотерапия имеет зарегистрированные показания Минздрава; отечественная альтернатива , Медозонс-БМ. | Z80: Гостевой опыт | AA80: B | AB80: Нет
A81: 80 | B81: Кухня и F&B | C81: Хлебопекарная печь | D81: Подовая/конвекционная хлебопекарная печь | E81: MIWE Condo 3.0608, MIWE econo, Wachtel | F81: Собственный хлеб, выпечка, безглютеновая продукция. | G81: Уровень Six Senses Place (велнес-плюс) | H81: Уровень Lanserhof/CLP (полный медицинский) | I81: 42000 | J81: 52000 | K81: 38000 | L81: Китай | M81: 5300000 | N81: 1 | O81: 15 | P81: 0.04 | Q81: 0 | R81: Ориентировочные цены MIWE/Wachtel (archiexpo, bakeryequipment.com) для трёхподовой модели. | S81: Средняя | T81: 2026-05 | U81: Органическая безглютеновая пекарня в стиле Lanserhof требует подовую печь с расстойкой. | Z81: Гостевой опыт | AA81: B | AB81: Нет
A82: 81 | B82: Кухня и F&B | C82: Холодный цех | D82: Станция холодной кухни (охлаждаемая зона подготовки и подачи) | E82: Inomak, True, Hoshizaki | F82: Салаты, raw-блюда, сашими, подача чистой кухни. | G82: Уровень Six Senses Place (велнес-плюс) | H82: Уровень SHA/Chenot (медицина-лайт) | I82: 35000 | J82: 42000 | K82: 28000 | L82: Китай | M82: 4400000 | N82: 1 | O82: 12 | P82: 0.04 | Q82: 0 | R82: Inomak/True (дилеры ЕС); линейная зона 6–8 м. | S82: Средняя | T82: 2026-05 | U82: Критично для raw- и clean-программ (стиль Chenot). | Z82: Гостевой опыт | AA82: C | AB82: Нет
A83: 82 | B83: Кухня и F&B | C83: Пароконвектомат | D83: Премиальный пароконвектомат (10×1/1 GN) | E83: Rational iCombi Pro 10-1/1, Convotherm 4 easyTouch | F83: Терапевтическая и ресторанная кухня; пар, конвекция, низкие температуры. | G83: Уровень Six Senses Place (велнес-плюс) | H83: Уровень Lanserhof/CLP (полный медицинский) | I83: 22000 | J83: 27000 | K83: 19000 | L83: Китай | M83: 2750000 | N83: 3 | O83: 12 | P83: 0.05 | Q83: 0 | R83: Дилеры Rational (WebstaurantStore, Buzz Catering, Nella) 2025; российский дилер ~+25% к ЕС. | S83: Высокая | T83: 2026-05 | U83: Три аппарата покрывают терапевтическую, горячую и банкетную кухни. | Z83: Гормезис, Гостевой опыт | AA83: C | AB83: Нет
A84: 83 | B84: Кухня и F&B | C84: Пароконвектомат (компакт) | D84: Компактный пароконвектомат (6×1/1 GN) | E84: Rational iCombi Pro 6-1/1, UNOX ChefTop | F84: Кондитерский цех, рыба, диетическая зона, room-service. | G84: Уровень Six Senses Place (велнес-плюс) | H84: Уровень SHA/Chenot (медицина-лайт) | I84: 14500 | J84: 18000 | K84: 12000 | L84: Китай | M84: 1800000 | N84: 2 | O84: 12 | P84: 0.05 | Q84: 0 | R84: Прайс Rational; дилеры UNOX (ЕС) 2025. | S84: Высокая | T84: 2026-05 | U84: Используется в кондитерской и дополнительной диетической линии. | Z84: Гостевой опыт | AA84: B | AB84: Нет
A85: 84 | B85: Кухня и F&B | C85: Посудомоечная машина (конвейерная) | D85: Конвейерная/тоннельная посудомоечная машина | E85: Hobart FT1000e, Winterhalter MTF, Meiko M-iQ | F85: Основная линия моечной для банкетов и ресторана. | G85: Уровень Six Senses Place (велнес-плюс) | H85: Уровень Lanserhof/CLP (полный медицинский) | I85: 75000 | J85: 90000 | K85: 60000 | L85: Китай | M85: 9500000 | N85: 1 | O85: 12 | P85: 0.05 | Q85: 0 | R85: Hobart, Winterhalter , дилеры ЕС 2025; hobartcorp.com. | S85: Высокая | T85: 2026-05 | U85: Обязательна для отеля 80–100 номеров с банкетной нагрузкой. | Z85: Гостевой опыт | AA85: B | AB85: Нет
A86: 85 | B86: Кухня и F&B | C86: Посудомоечные машины (фронтальные и подстольные) | D86: Подстольные и фронтальные стаканомойки и посудомойки (комплект) | E86: Hobart, Winterhalter UC-M, Meiko | F86: Бар, сокобар, станции подготовки. | G86: Уровень Six Senses Place (велнес-плюс) | H86: Уровень Lanserhof/CLP (полный медицинский) | I86: 28000 | J86: 34000 | K86: 22000 | L86: Китай | M86: 3500000 | N86: 4 | O86: 10 | P86: 0.05 | Q86: 0 | R86: Hobart/Winterhalter , дилеры ЕС 2025. | S86: Высокая | T86: 2026-05 | U86: Комплект из 4 машин закрывает бар, сокобар, банкеты и сателлит. | Z86: Гостевой опыт | AA86: B | AB86: Нет
... A130: 129 | B130: Сон и неврология | C130: Носимые устройства | D130: Премиальные носимые устройства (Oura/WHOOP/Apple Watch) | E130: Oura Ring Gen 4, WHOOP 5.0, Apple Watch Ultra 2 | F130: Стадии сна, ВСР, восстановление, тренировочная нагрузка , гостевой носимый гаджет в составе программы. | G130: Уровень SHA/Chenot (медицина-лайт) | H130: Уровень Lanserhof/CLP (полный медицинский) | I130: 8000 | J130: 9000 | K130: 6500 | L130: Китай | M130: 1100000 | N130: 25 | O130: 3 | P130: 0.1 | Q130: 0 | R130: Oura Ring $349–499; WHOOP $239 + $30 в месяц; Apple Watch Ultra 2 $799. Парк 25 единиц по средней цене €320. | S130: Высокая | T130: 2026-05 | U130: Парк выдаётся гостям на проживание. Подписки относятся к OPEX. По России: Apple Watch и Oura , параллельный импорт (надбавка 30%); WHOOP официально недоступен. | Z130: Инфраструктура | AA130: A | AB130: Нет
A131: 130 | B131: Телемедицина и цифровое здоровье | C131: Интеграция данных CGM | D131: Интеграция платформы CGM (тип Levels) | E131: Levels Health API, Nutrisense, Veri | F131: Передача данных непрерывных глюкометров в платформу долголетия. | G131: Уровень Six Senses Place (велнес-плюс) | H131: Уровень SHA/Chenot (медицина-лайт) | I131: 18000 | J131: 22000 | K131: 15000 | L131: Сингапур | M131: 2200000 | N131: 1 | O131: 5 | P131: 0 | Q131: 0 | R131: Levels API B2B / Nutrisense; ориентировочная стоимость интеграции. | S131: Низкая | T131: 2026-05 | U131: Сенсоры тарифицируются отдельно по гостю. По России: Abbott Libre , параллельным импортом; портал , российская разработка. | V131: 14000 | W131: 17000 | X131: 11000 | Y131: 1400000 | Z131: Инфраструктура, Диагностика | AA131: B | AB131: Нет
A132: 131 | B132: Телемедицина и цифровое здоровье | C132: Платформа постгостевого коучинга | D132: Приложение для коучинга и консьерж-сервиса (после выезда) | E132: MindBody Plus, Healthie, custom on Twilio | F132: Индивидуальный коучинг, контент и удержание клиента в течение 6–12 месяцев после визита. | G132: Уровень Six Senses Place (велнес-плюс) | H132: Уровень Lanserhof/CLP (полный медицинский) | I132: 65000 | J132: 80000 | K132: 55000 | L132: Сингапур | M132: 7500000 | N132: 1 | O132: 5 | P132: 0 | Q132: 1 | R132: Healthie / индивидуальная разработка; референс модели Lanserhof@home. | S132: Низкая | T132: 2026-05 | U132: Критичный драйвер выручки и возврата гостей , формирует ARR через подписку. Штатный показатель , численность коучей. | V132: 30000 | W132: 38000 | X132: 24000 | Y132: 2400000 | Z132: Диагностика | AA132: B | AB132: Нет
A133: 132 | B133: Телемедицина и цифровое здоровье | C133: Платформа видеоконсультаций | D133: HIPAA/GDPR-совместимая телемедицинская платформа | E133: Doxy.me Enterprise, Teladoc B2B, Amwell | F133: Видеоконсультации с врачами долголетия после визита. | G133: Уровень Six Senses Place (велнес-плюс) | H133: Уровень Lanserhof/CLP (полный медицинский) | I133: 25000 | J133: 32000 | K133: 22000 | L133: Сингапур | M133: 2500000 | N133: 1 | O133: 5 | P133: 0 | Q133: 0 | R133: Doxy.me Clinic $50 за пользователя в месяц; Enterprise , индивидуально; ~30–40 пользователей. | S133: Высокая | T133: 2026-05 | U133: По России: используются российские альтернативы (Mednote, Doctis) из-за GDPR/152-ФЗ и санкций. | V133: 22000 | W133: 28000 | X133: 18000 | Y133: 1800000 | Z133: Диагностика | AA133: B | AB133: Нет
A134: 133 | B134: Телемедицина и цифровое здоровье | C134: Носимые устройства , WHOOP/Garmin | D134: WHOOP Unite + Garmin Health (корпоративный пакет) | E134: WHOOP Unite, Garmin Health enterprise | F134: Учёт нагрузки и восстановления, коучинг по перформансу и долголетию. | G134: Опциональный апселл | H134: Опциональный апселл | I134: 35000 | J134: 42000 | K134: 28000 | L134: Сингапур | M134: 4200000 | N134: 1 | O134: 4 | P134: 0 | Q134: 0 | R134: WHOOP Unite (200+ корпоративных клиентов, prnewswire 2022); Garmin Health B2B. | S134: Низкая | T134: 2026-05 | U134: Опционально как дополнение к Oura. По России: оборудование , параллельным импортом. | V134: 25000 | W134: 30000 | X134: 20000 | Y134: 2400000 | Z134: Диагностика | AA134: A | AB134: Нет
A135: 134 | B135: Телемедицина и цифровое здоровье | C135: Носимые устройства , кольца | D135: Корпоративное развёртывание Oura Ring | E135: Oura for Business, Ultrahuman Ring, RingConn | F135: Отслеживание сна, ВСР и восстановления; долгосрочный крючок вовлечения. | G135: Уровень Six Senses Place (велнес-плюс) | H135: Уровень Lanserhof/CLP (полный медицинский) | I135: 65000 | J135: 80000 | K135: 55000 | L135: Сингапур | M135: 7500000 | N135: 1 | O135: 4 | P135: 0 | Q135: 0 | R135: Oura for Business B2B (sacra.com , 23% выручки); ~200 колец по $300 плюс дашборд. | S135: Средняя | T135: 2026-05 | U135: Стартовый парк 150–250 колец и B2B-дашборд; ежегодное пополнение ~25%. | V135: 18000 | W135: 22000 | X135: 14000 | Y135: 1800000 | Z135: Инфраструктура, Гостевой опыт | AA135: C | AB135: Нет

Sheet Сводка CapEx по уровням
A1: СВОДКА CapEx ПО УРОВНЯМ
A2: Живой свод из реестра через SUMPRODUCT. Меняйте цены в реестре , итоги обновятся.
A3: keys_count | B3: 90 | C3: ← редактируемый параметр (середина диапазона 80–100 номеров)
A4: Курс RUB/EUR | B4: 92
A5: Курс RUB/USD | B5: 85
A7: РЕГИОН , Европа (€)
A8: Группа | B8: Уровень Lanserhof/CLP (полный медицинский) | C8: Уровень SHA/Chenot (медицина-лайт) | D8: Уровень Six Senses Place (велнес-плюс)
A9: Итого медицинский CapEx | B9: =SUMPRODUCT((((1*('Реестр оборудования'!$G$2:$G$135="Уровень Six Senses Place (велнес-плюс)")+2*('Реестр оборудования'!$G$2:$G$135="Уровень SHA/Chenot (медицина-лайт)")+3*('Реестр оборудования'!$G$2:$G$135="Уровень Lanserhof/CLP (полный медицинский)"))>0)*((1*('Реестр оборудования'!$G$2:$G$135="Уровень Six Senses Place (велнес-плюс)")+2*('Реестр оборудования'!$G$2:$G$135="Уровень SHA/Chenot (медицина-лайт)")+3*('Реестр оборудования'!$G$2:$G$135="Уровень Lanserhof/CLP (полный медицинский)"))<=3))*(('Реестр оборудования'!$B$2:$B$135="Лучевая диагностика")+('Реестр оборудования'!$B$2:$B$135="Лаборатория и биомаркеры")+('Реестр оборудования'!$B$2:$B$135="Кардиология и пульмонология")+('Реестр оборудования'!$B$2:$B$135="Сон и неврология")+('Реестр оборудования'!$B$2:$B$135="Инфузионная терапия")+('Реестр оборудования'!$B$2:$B$135="Эстетика и регенеративные процедуры")+('Реестр оборудования'!$B$2:$B$135="Нутрициология и ЖКТ-диагностика")+('Реестр оборудования'!$B$2:$B$135="Состав тела и функциональная диагностика")+('Реестр оборудования'!$B$2:$B$135="Телемедицина и цифровое здоровье"))*IFERROR('Реестр оборудования'!$N$2:$N$135+0,0)*IFERROR('Реестр оборудования'!$I$2:$I$135+0,0)) -> 3250000 | C9: =SUMPRODUCT((((1*('Реестр оборудования'!$G$2:$G$135="Уровень Six Senses Place (велнес-плюс)")+2*('Реестр оборудования'!$G$2:$G$135="Уровень SHA/Chenot (медицина-лайт)")+3*('Реестр оборудования'!$G$2:$G$135="Уровень Lanserhof/CLP (полный медицинский)"))>0)*((1*('Реестр оборудования'!$G$2:$G$135="Уровень Six Senses Place (велнес-плюс)")+2*('Реестр оборудования'!$G$2:$G$135="Уровень SHA/Chenot (медицина-лайт)")+3*('Реестр оборудования'!$G$2:$G$135="Уровень Lanserhof/CLP (полный медицинский)"))<=2))*(('Реестр оборудования'!$B$2:$B$135="Лучевая диагностика")+('Реестр оборудования'!$B$2:$B$135="Лаборатория и биомаркеры")+('Реестр оборудования'!$B$2:$B$135="Кардиология и пульмонология")+('Реестр оборудования'!$B$2:$B$135="Сон и неврология")+('Реестр оборудования'!$B$2:$B$135="Инфузионная терапия")+('Реестр оборудования'!$B$2:$B$135="Эстетика и регенеративные процедуры")+('Реестр оборудования'!$B$2:$B$135="Нутрициология и ЖКТ-диагностика")+('Реестр оборудования'!$B$2:$B$135="Состав тела и функциональная диагностика")+('Реестр оборудования'!$B$2:$B$135="Телемедицина и цифровое здоровье"))*IFERROR('Реестр оборудования'!$N$2:$N$135+0,0)*IFERROR('Реестр оборудования'!$I$2:$I$135+0,0)) -> 2200000 | D9: =SUMPRODUCT((((1*('Реестр оборудования'!$G$2:$G$135="Уровень Six Senses Place (велнес-плюс)")+2*('Реестр оборудования'!$G$2:$G$135="Уровень SHA/Chenot (медицина-лайт)")+3*('Реестр оборудования'!$G$2:$G$135="Уровень Lanserhof/CLP (полный медицинский)"))>0)*((1*('Реестр оборудования'!$G$2:$G$135="Уровень Six Senses Place (велнес-плюс)")+2*('Реестр оборудования'!$G$2:$G$135="Уровень SHA/Chenot (медицина-лайт)")+3*('Реестр оборудования'!$G$2:$G$135="Уровень Lanserhof/CLP (полный медицинский)"))<=1))*(('Реестр оборудования'!$B$2:$B$135="Лучевая диагностика")+('Реестр оборудования'!$B$2:$B$135="Лаборатория и биомаркеры")+('Реестр оборудования'!$B$2:$B$135="Кардиология и пульмонология")+('Реестр оборудования'!$B$2:$B$135="Сон и неврология")+('Реестр оборудования'!$B$2:$B$135="Инфузионная терапия")+('Реестр оборудования'!$B$2:$B$135="Эстетика и регенеративные процедуры")+('Реестр оборудования'!$B$2:$B$135="Нутрициология и ЖКТ-диагностика")+('Реестр оборудования'!$B$2:$B$135="Состав тела и функциональная диагностика")+('Реестр оборудования'!$B$2:$B$135="Телемедицина и цифровое здоровье"))*IFERROR('Реестр оборудования'!$N$2:$N$135+0,0)*IFERROR('Реестр оборудования'!$I$2:$I$135+0,0)) -> 300000
A10: Итого SPA и восстановление | B10: =SUMPRODUCT((((1*('Реестр оборудования'!$G$2:$G$135="Уровень Six Senses Place (велнес-плюс)")+2*('Реестр оборудования'!$G$2:$G$135="Уровень SHA/Chenot (медицина-лайт)")+3*('Реестр оборудования'!$G$2:$G$135="Уровень Lanserhof/CLP (полный медицинский)"))>0)*((1*('Реестр оборудования'!$G$2:$G$135="Уровень Six Senses Place (велнес-плюс)")+2*('Реестр оборудования'!$G$2:$G$135="Уровень SHA/Chenot (медицина-лайт)")+3*('Реестр оборудования'!$G$2:$G$135="Уровень Lanserhof/CLP (полный медицинский)"))<=3))*(('Реестр оборудования'!$B$2:$B$135="Гидротерапия и SPA")+('Реестр оборудования'!$B$2:$B$135="Криотерапия и термальные зоны"))*IFERROR('Реестр оборудования'!$N$2:$N$135+0,0)*IFERROR('Реестр оборудования'!$I$2:$I$135+0,0)) -> 1064000 | C10: =SUMPRODUCT((((1*('Реестр оборудования'!$G$2:$G$135="Уровень Six Senses Place (велнес-плюс)")+2*('Реестр оборудования'!$G$2:$G$135="Уровень SHA/Chenot (медицина-лайт)")+3*('Реестр оборудования'!$G$2:$G$135="Уровень Lanserhof/CLP (полный медицинский)"))>0)*((1*('Реестр оборудования'!$G$2:$G$135="Уровень Six Senses Place (велнес-плюс)")+2*('Реестр оборудования'!$G$2:$G$135="Уровень SHA/Chenot (медицина-лайт)")+3*('Реестр оборудования'!$G$2:$G$135="Уровень Lanserhof/CLP (полный медицинский)"))<=2))*(('Реестр оборудования'!$B$2:$B$135="Гидротерапия и SPA")+('Реестр оборудования'!$B$2:$B$135="Криотерапия и термальные зоны"))*IFERROR('Реестр оборудования'!$N$2:$N$135+0,0)*IFERROR('Реестр оборудования'!$I$2:$I$135+0,0)) -> 1064000 | D10: =SUMPRODUCT((((1*('Реестр оборудования'!$G$2:$G$135="Уровень Six Senses Place (велнес-плюс)")+2*('Реестр оборудования'!$G$2:$G$135="Уровень SHA/Chenot (медицина-лайт)")+3*('Реестр оборудования'!$G$2:$G$135="Уровень Lanserhof/CLP (полный медицинский)"))>0)*((1*('Реестр оборудования'!$G$2:$G$135="Уровень Six Senses Place (велнес-плюс)")+2*('Реестр оборудования'!$G$2:$G$135="Уровень SHA/Chenot (медицина-лайт)")+3*('Реестр оборудования'!$G$2:$G$135="Уровень Lanserhof/CLP (полный медицинский)"))<=1))*(('Реестр оборудования'!$B$2:$B$135="Гидротерапия и SPA")+('Реестр оборудования'!$B$2:$B$135="Криотерапия и термальные зоны"))*IFERROR('Реестр оборудования'!$N$2:$N$135+0,0)*IFERROR('Реестр оборудования'!$I$2:$I$135+0,0)) -> 1064000
A11: Итого фитнес и движение | B11: =SUMPRODUCT((((1*('Реестр оборудования'!$G$2:$G$135="Уровень Six Senses Place (велнес-плюс)")+2*('Реестр оборудования'!$G$2:$G$135="Уровень SHA/Chenot (медицина-лайт)")+3*('Реестр оборудования'!$G$2:$G$135="Уровень Lanserhof/CLP (полный медицинский)"))>0)*((1*('Реестр оборудования'!$G$2:$G$135="Уровень Six Senses Place (велнес-плюс)")+2*('Реестр оборудования'!$G$2:$G$135="Уровень SHA/Chenot (медицина-лайт)")+3*('Реестр оборудования'!$G$2:$G$135="Уровень Lanserhof/CLP (полный медицинский)"))<=3))*(('Реестр оборудования'!$B$2:$B$135="Движение и реабилитация")+('Реестр оборудования'!$B$2:$B$135="Тренажёрный зал и силовая зона"))*IFERROR('Реестр оборудования'!$N$2:$N$135+0,0)*IFERROR('Реестр оборудования'!$I$2:$I$135+0,0)) -> 720000 | C11: =SUMPRODUCT((((1*('Реестр оборудования'!$G$2:$G$135="Уровень Six Senses Place (велнес-плюс)")+2*('Реестр оборудования'!$G$2:$G$135="Уровень SHA/Chenot (медицина-лайт)")+3*('Реестр оборудования'!$G$2:$G$135="Уровень Lanserhof/CLP (полный медицинский)"))>0)*((1*('Реестр оборудования'!$G$2:$G$135="Уровень Six Senses Place (велнес-плюс)")+2*('Реестр оборудования'!$G$2:$G$135="Уровень SHA/Chenot (медицина-лайт)")+3*('Реестр оборудования'!$G$2:$G$135="Уровень Lanserhof/CLP (полный медицинский)"))<=2))*(('Реестр оборудования'!$B$2:$B$135="Движение и реабилитация")+('Реестр оборудования'!$B$2:$B$135="Тренажёрный зал и силовая зона"))*IFERROR('Реестр оборудования'!$N$2:$N$135+0,0)*IFERROR('Реестр оборудования'!$I$2:$I$135+0,0)) -> 540000 | D11: =SUMPRODUCT((((1*('Реестр оборудования'!$G$2:$G$135="Уровень Six Senses Place (велнес-плюс)")+2*('Реестр оборудования'!$G$2:$G$135="Уровень SHA/Chenot (медицина-лайт)")+3*('Реестр оборудования'!$G$2:$G$135="Уровень Lanserhof/CLP (полный медицинский)"))>0)*((1*('Реестр оборудования'!$G$2:$G$135="Уровень Six Senses Place (велнес-плюс)")+2*('Реестр оборудования'!$G$2:$G$135="Уровень SHA/Chenot (медицина-лайт)")+3*('Реестр оборудования'!$G$2:$G$135="Уровень Lanserhof/CLP (полный медицинский)"))<=1))*(('Реестр оборудования'!$B$2:$B$135="Движение и реабилитация")+('Реестр оборудования'!$B$2:$B$135="Тренажёрный зал и силовая зона"))*IFERROR('Реестр оборудования'!$N$2:$N$135+0,0)*IFERROR('Реестр оборудования'!$I$2:$I$135+0,0)) -> 540000
A12: Итого ИТ и ПО (единовременный CapEx) | B12: =SUMPRODUCT((((1*('Реестр оборудования'!$G$2:$G$135="Уровень Six Senses Place (велнес-плюс)")+2*('Реестр оборудования'!$G$2:$G$135="Уровень SHA/Chenot (медицина-лайт)")+3*('Реестр оборудования'!$G$2:$G$135="Уровень Lanserhof/CLP (полный медицинский)"))>0)*((1*('Реестр оборудования'!$G$2:$G$135="Уровень Six Senses Place (велнес-плюс)")+2*('Реестр оборудования'!$G$2:$G$135="Уровень SHA/Chenot (медицина-лайт)")+3*('Реестр оборудования'!$G$2:$G$135="Уровень Lanserhof/CLP (полный медицинский)"))<=3))*(('Реестр оборудования'!$B$2:$B$135="ИТ, МИС, ПО для пациентов"))*IFERROR('Реестр оборудования'!$N$2:$N$135+0,0)*IFERROR('Реестр оборудования'!$I$2:$I$135+0,0)) -> 855000 | C12: =SUMPRODUCT((((1*('Реестр оборудования'!$G$2:$G$135="Уровень Six Senses Place (велнес-плюс)")+2*('Реестр оборудования'!$G$2:$G$135="Уровень SHA/Chenot (медицина-лайт)")+3*('Реестр оборудования'!$G$2:$G$135="Уровень Lanserhof/CLP (полный медицинский)"))>0)*((1*('Реестр оборудования'!$G$2:$G$135="Уровень Six Senses Place (велнес-плюс)")+2*('Реестр оборудования'!$G$2:$G$135="Уровень SHA/Chenot (медицина-лайт)")+3*('Реестр оборудования'!$G$2:$G$135="Уровень Lanserhof/CLP (полный медицинский)"))<=2))*(('Реестр оборудования'!$B$2:$B$135="ИТ, МИС, ПО для пациентов"))*IFERROR('Реестр оборудования'!$N$2:$N$135+0,0)*IFERROR('Реестр оборудования'!$I$2:$I$135+0,0)) -> 855000 | D12: =SUMPRODUCT((((1*('Реестр оборудования'!$G$2:$G$135="Уровень Six Senses Place (велнес-плюс)")+2*('Реестр оборудования'!$G$2:$G$135="Уровень SHA/Chenot (медицина-лайт)")+3*('Реестр оборудования'!$G$2:$G$135="Уровень Lanserhof/CLP (полный медицинский)"))>0)*((1*('Реестр оборудования'!$G$2:$G$135="Уровень Six Senses Place (велнес-плюс)")+2*('Реестр оборудования'!$G$2:$G$135="Уровень SHA/Chenot (медицина-лайт)")+3*('Реестр оборудования'!$G$2:$G$135="Уровень Lanserhof/CLP (полный медицинский)"))<=1))*(('Реестр оборудования'!$B$2:$B$135="ИТ, МИС, ПО для пациентов"))*IFERROR('Реестр оборудования'!$N$2:$N$135+0,0)*IFERROR('Реестр оборудования'!$I$2:$I$135+0,0)) -> 760000
A13: Итого кухня и F&B | B13: =SUMPRODUCT((((1*('Реестр оборудования'!$G$2:$G$135="Уровень Six Senses Place (велнес-плюс)")+2*('Реестр оборудования'!$G$2:$G$135="Уровень SHA/Chenot (медицина-лайт)")+3*('Реестр оборудования'!$G$2:$G$135="Уровень Lanserhof/CLP (полный медицинский)"))>0)*((1*('Реестр оборудования'!$G$2:$G$135="Уровень Six Senses Place (велнес-плюс)")+2*('Реестр оборудования'!$G$2:$G$135="Уровень SHA/Chenot (медицина-лайт)")+3*('Реестр оборудования'!$G$2:$G$135="Уровень Lanserhof/CLP (полный медицинский)"))<=3))*(('Реестр оборудования'!$B$2:$B$135="Кухня и F&B"))*IFERROR('Реестр оборудования'!$N$2:$N$135+0,0)*IFERROR('Реестр оборудования'!$I$2:$I$135+0,0)) -> 630000 | C13: =SUMPRODUCT((((1*('Реестр оборудования'!$G$2:$G$135="Уровень Six Senses Place (велнес-плюс)")+2*('Реестр оборудования'!$G$2:$G$135="Уровень SHA/Chenot (медицина-лайт)")+3*('Реестр оборудования'!$G$2:$G$135="Уровень Lanserhof/CLP (полный медицинский)"))>0)*((1*('Реестр оборудования'!$G$2:$G$135="Уровень Six Senses Place (велнес-плюс)")+2*('Реестр оборудования'!$G$2:$G$135="Уровень SHA/Chenot (медицина-лайт)")+3*('Реестр оборудования'!$G$2:$G$135="Уровень Lanserhof/CLP (полный медицинский)"))<=2))*(('Реестр оборудования'!$B$2:$B$135="Кухня и F&B"))*IFERROR('Реестр оборудования'!$N$2:$N$135+0,0)*IFERROR('Реестр оборудования'!$I$2:$I$135+0,0)) -> 630000 | D13: =SUMPRODUCT((((1*('Реестр оборудования'!$G$2:$G$135="Уровень Six Senses Place (велнес-плюс)")+2*('Реестр оборудования'!$G$2:$G$135="Уровень SHA/Chenot (медицина-лайт)")+3*('Реестр оборудования'!$G$2:$G$135="Уровень Lanserhof/CLP (полный медицинский)"))>0)*((1*('Реестр оборудования'!$G$2:$G$135="Уровень Six Senses Place (велнес-плюс)")+2*('Реестр оборудования'!$G$2:$G$135="Уровень SHA/Chenot (медицина-лайт)")+3*('Реестр оборудования'!$G$2:$G$135="Уровень Lanserhof/CLP (полный медицинский)"))<=1))*(('Реестр оборудования'!$B$2:$B$135="Кухня и F&B"))*IFERROR('Реестр оборудования'!$N$2:$N$135+0,0)*IFERROR('Реестр оборудования'!$I$2:$I$135+0,0)) -> 630000
A14: Итого медицинская инфраструктура | B14: =SUMPRODUCT((((1*('Реестр оборудования'!$G$2:$G$135="Уровень Six Senses Place (велнес-плюс)")+2*('Реестр оборудования'!$G$2:$G$135="Уровень SHA/Chenot (медицина-лайт)")+3*('Реестр оборудования'!$G$2:$G$135="Уровень Lanserhof/CLP (полный медицинский)"))>0)*((1*('Реестр оборудования'!$G$2:$G$135="Уровень Six Senses Place (велнес-плюс)")+2*('Реестр оборудования'!$G$2:$G$135="Уровень SHA/Chenot (медицина-лайт)")+3*('Реестр оборудования'!$G$2:$G$135="Уровень Lanserhof/CLP (полный медицинский)"))<=3))*(('Реестр оборудования'!$B$2:$B$135="Медицинская инфраструктура"))*IFERROR('Реестр оборудования'!$N$2:$N$135+0,0)*IFERROR('Реестр оборудования'!$I$2:$I$135+0,0)) -> 910000 | C14: =SUMPRODUCT((((1*('Реестр оборудования'!$G$2:$G$135="Уровень Six Senses Place (велнес-плюс)")+2*('Реестр оборудования'!$G$2:$G$135="Уровень SHA/Chenot (медицина-лайт)")+3*('Реестр оборудования'!$G$2:$G$135="Уровень Lanserhof/CLP (полный медицинский)"))>0)*((1*('Реестр оборудования'!$G$2:$G$135="Уровень Six Senses Place (велнес-плюс)")+2*('Реестр оборудования'!$G$2:$G$135="Уровень SHA/Chenot (медицина-лайт)")+3*('Реестр оборудования'!$G$2:$G$135="Уровень Lanserhof/CLP (полный медицинский)"))<=2))*(('Реестр оборудования'!$B$2:$B$135="Медицинская инфраструктура"))*IFERROR('Реестр оборудования'!$N$2:$N$135+0,0)*IFERROR('Реестр оборудования'!$I$2:$I$135+0,0)) -> 260000 | D14: =SUMPRODUCT((((1*('Реестр оборудования'!$G$2:$G$135="Уровень Six Senses Place (велнес-плюс)")+2*('Реестр оборудования'!$G$2:$G$135="Уровень SHA/Chenot (медицина-лайт)")+3*('Реестр оборудования'!$G$2:$G$135="Уровень Lanserhof/CLP (полный медицинский)"))>0)*((1*('Реестр оборудования'!$G$2:$G$135="Уровень Six Senses Place (велнес-плюс)")+2*('Реестр оборудования'!$G$2:$G$135="Уровень SHA/Chenot (медицина-лайт)")+3*('Реестр оборудования'!$G$2:$G$135="Уровень Lanserhof/CLP (полный медицинский)"))<=1))*(('Реестр оборудования'!$B$2:$B$135="Медицинская инфраструктура"))*IFERROR('Реестр оборудования'!$N$2:$N$135+0,0)*IFERROR('Реестр оборудования'!$I$2:$I$135+0,0)) -> 0
A15: ИТОГО CapEx | B15: =SUM(B9:B14) -> 7429000 | C15: =SUM(C9:C14) -> 5549000 | D15: =SUM(D9:D14) -> 3294000
A16: CapEx на номер | B16: =B15/$B$3 -> 82544.444 | C16: =C15/$B$3 -> 61655.556 | D16: =D15/$B$3 -> 36600
A18: РЕГИОН , Северная Америка ($)
A19: Группа | B19: Уровень Lanserhof/CLP (полный медицинский) | C19: Уровень SHA/Chenot (медицина-лайт) | D19: Уровень Six Senses Place (велнес-плюс)
A20: Итого медицинский CapEx | B20: =SUMPRODUCT((((1*('Реестр оборудования'!$G$2:$G$135="Уровень Six Senses Place (велнес-плюс)")+2*('Реестр оборудования'!$G$2:$G$135="Уровень SHA/Chenot (медицина-лайт)")+3*('Реестр оборудования'!$G$2:$G$135="Уровень Lanserhof/CLP (полный медицинский)"))>0)*((1*('Реестр оборудования'!$G$2:$G$135="Уровень Six Senses Place (велнес-плюс)")+2*('Реестр оборудования'!$G$2:$G$135="Уровень SHA/Chenot (медицина-лайт)")+3*('Реестр оборудования'!$G$2:$G$135="Уровень Lanserhof/CLP (полный медицинский)"))<=3))*(('Реестр оборудования'!$B$2:$B$135="Лучевая диагностика")+('Реестр оборудования'!$B$2:$B$135="Лаборатория и биомаркеры")+('Реестр оборудования'!$B$2:$B$135="Кардиология и пульмонология")+('Реестр оборудования'!$B$2:$B$135="Сон и неврология")+('Реестр оборудования'!$B$2:$B$135="Инфузионная терапия")+('Реестр оборудования'!$B$2:$B$135="Эстетика и регенеративные процедуры")+('Реестр оборудования'!$B$2:$B$135="Нутрициология и ЖКТ-диагностика")+('Реестр оборудования'!$B$2:$B$135="Состав тела и функциональная диагностика")+('Реестр оборудования'!$B$2:$B$135="Телемедицина и цифровое здоровье"))*IFERROR('Реестр оборудования'!$N$2:$N$135+0,0)*IFERROR('Реестр оборудования'!$J$2:$J$135+0,0)) -> 0 | C20: =SUMPRODUCT((((1*('Реестр оборудования'!$G$2:$G$135="Уровень Six Senses Place (велнес-плюс)")+2*('Реестр оборудования'!$G$2:$G$135="Уровень SHA/Chenot (медицина-лайт)")+3*('Реестр оборудования'!$G$2:$G$135="Уровень Lanserhof/CLP (полный медицинский)"))>0)*((1*('Реестр оборудования'!$G$2:$G$135="Уровень Six Senses Place (велнес-плюс)")+2*('Реестр оборудования'!$G$2:$G$135="Уровень SHA/Chenot (медицина-лайт)")+3*('Реестр оборудования'!$G$2:$G$135="Уровень Lanserhof/CLP (полный медицинский)"))<=2))*(('Реестр оборудования'!$B$2:$B$135="Лучевая диагностика")+('Реестр оборудования'!$B$2:$B$135="Лаборатория и биомаркеры")+('Реестр оборудования'!$B$2:$B$135="Кардиология и пульмонология")+('Реестр оборудования'!$B$2:$B$135="Сон и неврология")+('Реестр оборудования'!$B$2:$B$135="Инфузионная терапия")+('Реестр оборудования'!$B$2:$B$135="Эстетика и регенеративные процедуры")+('Реестр оборудования'!$B$2:$B$135="Нутрициология и ЖКТ-диагностика")+('Реестр оборудования'!$B$2:$B$135="Состав тела и функциональная диагностика")+('Реестр оборудования'!$B$2:$B$135="Телемедицина и цифровое здоровье"))*IFERROR('Реестр оборудования'!$N$2:$N$135+0,0)*IFERROR('Реестр оборудования'!$J$2:$J$135+0,0)) -> 0 | D20: =SUMPRODUCT((((1*('Реестр оборудования'!$G$2:$G$135="Уровень Six Senses Place (велнес-плюс)")+2*('Реестр оборудования'!$G$2:$G$135="Уровень SHA/Chenot (медицина-лайт)")+3*('Реестр оборудования'!$G$2:$G$135="Уровень Lanserhof/CLP (полный медицинский)"))>0)*((1*('Реестр оборудования'!$G$2:$G$135="Уровень Six Senses Place (велнес-плюс)")+2*('Реестр оборудования'!$G$2:$G$135="Уровень SHA/Chenot (медицина-лайт)")+3*('Реестр оборудования'!$G$2:$G$135="Уровень Lanserhof/CLP (полный медицинский)"))<=1))*(('Реестр оборудования'!$B$2:$B$135="Лучевая диагностика")+('Реестр оборудования'!$B$2:$B$135="Лаборатория и биомаркеры")+('Реестр оборудования'!$B$2:$B$135="Кардиология и пульмонология")+('Реестр оборудования'!$B$2:$B$135="Сон и неврология")+('Реестр оборудования'!$B$2:$B$135="Инфузионная терапия")+('Реестр оборудования'!$B$2:$B$135="Эстетика и регенеративные процедуры")+('Реестр оборудования'!$B$2:$B$135="Нутрициология и ЖКТ-диагностика")+('Реестр оборудования'!$B$2:$B$135="Состав тела и функциональная диагностика")+('Реестр оборудования'!$B$2:$B$135="Телемедицина и цифровое здоровье"))*IFERROR('Реестр оборудования'!$N$2:$N$135+0,0)*IFERROR('Реестр оборудования'!$J$2:$J$135+0,0)) -> 0
A21: Итого SPA и восстановление | B21: =SUMPRODUCT((((1*('Реестр оборудования'!$G$2:$G$135="Уровень Six Senses Place (велнес-плюс)")+2*('Реестр оборудования'!$G$2:$G$135="Уровень SHA/Chenot (медицина-лайт)")+3*('Реестр оборудования'!$G$2:$G$135="Уровень Lanserhof/CLP (полный медицинский)"))>0)*((1*('Реестр оборудования'!$G$2:$G$135="Уровень Six Senses Place (велнес-плюс)")+2*('Реестр оборудования'!$G$2:$G$135="Уровень SHA/Chenot (медицина-лайт)")+3*('Реестр оборудования'!$G$2:$G$135="Уровень Lanserhof/CLP (полный медицинский)"))<=3))*(('Реестр оборудования'!$B$2:$B$135="Гидротерапия и SPA")+('Реестр оборудования'!$B$2:$B$135="Криотерапия и термальные зоны"))*IFERROR('Реестр оборудования'!$N$2:$N$135+0,0)*IFERROR('Реестр оборудования'!$J$2:$J$135+0,0)) -> 798000 | C21: =SUMPRODUCT((((1*('Реестр оборудования'!$G$2:$G$135="Уровень Six Senses Place (велнес-плюс)")+2*('Реестр оборудования'!$G$2:$G$135="Уровень SHA/Chenot (медицина-лайт)")+3*('Реестр оборудования'!$G$2:$G$135="Уровень Lanserhof/CLP (полный медицинский)"))>0)*((1*('Реестр оборудования'!$G$2:$G$135="Уровень Six Senses Place (велнес-плюс)")+2*('Реестр оборудования'!$G$2:$G$135="Уровень SHA/Chenot (медицина-лайт)")+3*('Реестр оборудования'!$G$2:$G$135="Уровень Lanserhof/CLP (полный медицинский)"))<=2))*(('Реестр оборудования'!$B$2:$B$135="Гидротерапия и SPA")+('Реестр оборудования'!$B$2:$B$135="Криотерапия и термальные зоны"))*IFERROR('Реестр оборудования'!$N$2:$N$135+0,0)*IFERROR('Реестр оборудования'!$J$2:$J$135+0,0)) -> 798000 | D21: =SUMPRODUCT((((1*('Реестр оборудования'!$G$2:$G$135="Уровень Six Senses Place (велнес-плюс)")+2*('Реестр оборудования'!$G$2:$G$135="Уровень SHA/Chenot (медицина-лайт)")+3*('Реестр оборудования'!$G$2:$G$135="Уровень Lanserhof/CLP (полный медицинский)"))>0)*((1*('Реестр оборудования'!$G$2:$G$135="Уровень Six Senses Place (велнес-плюс)")+2*('Реестр оборудования'!$G$2:$G$135="Уровень SHA/Chenot (медицина-лайт)")+3*('Реестр оборудования'!$G$2:$G$135="Уровень Lanserhof/CLP (полный медицинский)"))<=1))*(('Реестр оборудования'!$B$2:$B$135="Гидротерапия и SPA")+('Реестр оборудования'!$B$2:$B$135="Криотерапия и термальные зоны"))*IFERROR('Реестр оборудования'!$N$2:$N$135+0,0)*IFERROR('Реестр оборудования'!$J$2:$J$135+0,0)) -> 798000
A22: Итого фитнес и движение | B22: =SUMPRODUCT((((1*('Реестр оборудования'!$G$2:$G$135="Уровень Six Senses Place (велнес-плюс)")+2*('Реестр оборудования'!$G$2:$G$135="Уровень SHA/Chenot (медицина-лайт)")+3*('Реестр оборудования'!$G$2:$G$135="Уровень Lanserhof/CLP (полный медицинский)"))>0)*((1*('Реестр оборудования'!$G$2:$G$135="Уровень Six Senses Place (велнес-плюс)")+2*('Реестр оборудования'!$G$2:$G$135="Уровень SHA/Chenot (медицина-лайт)")+3*('Реестр оборудования'!$G$2:$G$135="Уровень Lanserhof/CLP (полный медицинский)"))<=3))*(('Реестр оборудования'!$B$2:$B$135="Движение и реабилитация")+('Реестр оборудования'!$B$2:$B$135="Тренажёрный зал и силовая зона"))*IFERROR('Реестр оборудования'!$N$2:$N$135+0,0)*IFERROR('Реестр оборудования'!$J$2:$J$135+0,0)) -> 896000 | C22: =SUMPRODUCT((((1*('Реестр оборудования'!$G$2:$G$135="Уровень Six Senses Place (велнес-плюс)")+2*('Реестр оборудования'!$G$2:$G$135="Уровень SHA/Chenot (медицина-лайт)")+3*('Реестр оборудования'!$G$2:$G$135="Уровень Lanserhof/CLP (полный медицинский)"))>0)*((1*('Реестр оборудования'!$G$2:$G$135="Уровень Six Senses Place (велнес-плюс)")+2*('Реестр оборудования'!$G$2:$G$135="Уровень SHA/Chenot (медицина-лайт)")+3*('Реестр оборудования'!$G$2:$G$135="Уровень Lanserhof/CLP (полный медицинский)"))<=2))*(('Реестр оборудования'!$B$2:$B$135="Движение и реабилитация")+('Реестр оборудования'!$B$2:$B$135="Тренажёрный зал и силовая зона"))*IFERROR('Реестр оборудования'!$N$2:$N$135+0,0)*IFERROR('Реестр оборудования'!$J$2:$J$135+0,0)) -> 672000 | D22: =SUMPRODUCT((((1*('Реестр оборудования'!$G$2:$G$135="Уровень Six Senses Place (велнес-плюс)")+2*('Реестр оборудования'!$G$2:$G$135="Уровень SHA/Chenot (медицина-лайт)")+3*('Реестр оборудования'!$G$2:$G$135="Уровень Lanserhof/CLP (полный медицинский)"))>0)*((1*('Реестр оборудования'!$G$2:$G$135="Уровень Six Senses Place (велнес-плюс)")+2*('Реестр оборудования'!$G$2:$G$135="Уровень SHA/Chenot (медицина-лайт)")+3*('Реестр оборудования'!$G$2:$G$135="Уровень Lanserhof/CLP (полный медицинский)"))<=1))*(('Реестр оборудования'!$B$2:$B$135="Движение и реабилитация")+('Реестр оборудования'!$B$2:$B$135="Тренажёрный зал и силовая зона"))*IFERROR('Реестр оборудования'!$N$2:$N$135+0,0)*IFERROR('Реестр оборудования'!$J$2:$J$135+0,0)) -> 672000
A23: Итого ИТ и ПО (единовременный CapEx) | B23: =SUMPRODUCT((((1*('Реестр оборудования'!$G$2:$G$135="Уровень Six Senses Place (велнес-плюс)")+2*('Реестр оборудования'!$G$2:$G$135="Уровень SHA/Chenot (медицина-лайт)")+3*('Реестр оборудования'!$G$2:$G$135="Уровень Lanserhof/CLP (полный медицинский)"))>0)*((1*('Реестр оборудования'!$G$2:$G$135="Уровень Six Senses Place (велнес-плюс)")+2*('Реестр оборудования'!$G$2:$G$135="Уровень SHA/Chenot (медицина-лайт)")+3*('Реестр оборудования'!$G$2:$G$135="Уровень Lanserhof/CLP (полный медицинский)"))<=3))*(('Реестр оборудования'!$B$2:$B$135="ИТ, МИС, ПО для пациентов"))*IFERROR('Реестр оборудования'!$N$2:$N$135+0,0)*IFERROR('Реестр оборудования'!$J$2:$J$135+0,0)) -> 90000 | C23: =SUMPRODUCT((((1*('Реестр оборудования'!$G$2:$G$135="Уровень Six Senses Place (велнес-плюс)")+2*('Реестр оборудования'!$G$2:$G$135="Уровень SHA/Chenot (медицина-лайт)")+3*('Реестр оборудования'!$G$2:$G$135="Уровень Lanserhof/CLP (полный медицинский)"))>0)*((1*('Реестр оборудования'!$G$2:$G$135="Уровень Six Senses Place (велнес-плюс)")+2*('Реестр оборудования'!$G$2:$G$135="Уровень SHA/Chenot (медицина-лайт)")+3*('Реестр оборудования'!$G$2:$G$135="Уровень Lanserhof/CLP (полный медицинский)"))<=2))*(('Реестр оборудования'!$B$2:$B$135="ИТ, МИС, ПО для пациентов"))*IFERROR('Реестр оборудования'!$N$2:$N$135+0,0)*IFERROR('Реестр оборудования'!$J$2:$J$135+0,0)) -> 90000 | D23: =SUMPRODUCT((((1*('Реестр оборудования'!$G$2:$G$135="Уровень Six Senses Place (велнес-плюс)")+2*('Реестр оборудования'!$G$2:$G$135="Уровень SHA/Chenot (медицина-лайт)")+3*('Реестр оборудования'!$G$2:$G$135="Уровень Lanserhof/CLP (полный медицинский)"))>0)*((1*('Реестр оборудования'!$G$2:$G$135="Уровень Six Senses Place (велнес-плюс)")+2*('Реестр оборудования'!$G$2:$G$135="Уровень SHA/Chenot (медицина-лайт)")+3*('Реестр оборудования'!$G$2:$G$135="Уровень Lanserhof/CLP (полный медицинский)"))<=1))*(('Реестр оборудования'!$B$2:$B$135="ИТ, МИС, ПО для пациентов"))*IFERROR('Реестр оборудования'!$N$2:$N$135+0,0)*IFERROR('Реестр оборудования'!$J$2:$J$135+0,0)) -> 80000
