Workbook

Sheet Cover
B2: Premium Longevity Resort — Capex Benchmark Study
B3: Equipment, Software, Spa, Kitchen & Medical Infrastructure across 4 regions
B5: Date issued | C5: 2026-05-03
B6: Tier coverage | C6: Lanserhof/CLP (full medical depth) | SHA/Chenot (medical-light) | Six Senses Place (wellness+)
B7: Property profile | C7: 80–100 keys (model uses 90 keys mid-point); premium-luxury positioning
B8: Regions priced | C8: Western Europe (EUR) | North America (USD) | Asia (USD, country-tagged) | Russia (RUB est.)
B9: Items priced | C9: 134 line items across 16 categories
B11: WORKBOOK CONTENTS
B12: Cover | C12: This page — methodology, tier definitions, color legend
B13: Equipment Master List | C13: All 134 line items with brand, prices in 4 regions, tier assignment, source, confidence
B14: Capex Summary by Tier | C14: Roll-up by tier x group x region. Live formulas — change Master List or keys_count to refresh.
B15: Payback & Revenue Logic | C15: Equipment payback blocks, procedure & package pricing, ADR uplift logic, payback bands
B16: Regional Cost Drivers | C16: Sanctions, customs/VAT, parallel import, domestic alternatives — Russia detail
B17: Sources & Methodology | C17: All sources cited + confidence assessment + recommended verification path
B20: TIER DEFINITIONS
B21: Six Senses Place-tier | C21: Wellness-plus. Premium spa, full thermal, full Pilates+gym, full kitchen, PMS+IT. NO medical center, no imaging, no in-house lab, no EHR. Items here are present in EVERY tier (the operational floor).
B22: SHA/Chenot-tier | C22: Medical-light. Adds ultrasound, DEXA, X-ray, basic lab analyzers, ECG suite, HSAT, IV chairs, FibroScan, RMR, mid-market EHR, basic medical infra.
B23: Lanserhof/CLP-tier | C23: Full medical depth. Adds MRI 3T+1.5T, CT, OCT, mammography, full PSG/EEG, ozone/IHHT/HBOT, aesthetic lasers, full PACS, full medical gas + generator + HEPA.
B24: Optional upsell | C24: Reported separately — Epic EHR, Cryolipolysis, ECG patch fleet, WHOOP/Garmin enterprise. NOT in tier base totals.
B27: COLOR-CODE LEGEND
B28: Hardcoded input | C28: Numbers a user can change for scenarios (unit prices, keys_count, FX)
B29: Formula / calculated | C29: Cells computed by the workbook from inputs above
B30: Cross-sheet link | C30: References to other sheets — keeps roll-ups in sync with the Master List
B31: Confidence fills | C31: Green = High, Yellow = Medium, Orange = Low — applied to Master List Confidence column.
B33: READING THIS WORKBOOK
C34: 1. The Master List is the single source of truth. Edit a price or quantity there — the Capex Summary updates via SUMPRODUCT.
C35: 2. Capex Summary uses tier inclusion logic: Six Senses items count in ALL 3 tiers; SHA items count in CLP + SHA; CLP items count only in CLP.
C36: 3. Software shows upfront capex AND annual subscription separately. Annual figures are opex (excluded from capex totals).
C37: 4. The Russia (RUB) column carries the LOWEST confidence — see Sources & Methodology for verification recommendations.
C38: 5. 'Capex per key' uses keys_count in cell B3 of the Capex Summary sheet (default 90 — editable).

Sheet Equipment Master List
A1: ID | B1: Category | C1: Subcategory | D1: Equipment item | E1: Brand examples | F1: Function | G1: Tier (corrected) | H1: Tier (research-assigned) | I1: Price — Western Europe (€) | J1: Price — North America (USD) | K1: Price — Asia (USD) | L1: Asia country | M1: Price — Russia est. (₽) | N1: Quantity (80–100 keys) | O1: Useful life (yrs) | P1: Annual maint (% capex) | Q1: Operator FTE | R1: Source | S1: Confidence | T1: Last verified | U1: Notes | V1: EU annual € (sw) | W1: NA annual $ (sw) | X1: Asia annual $ (sw) | Y1: Russia annual ₽ (sw)
A2: 1 | B2: Aesthetic & Regenerative | C2: Ablative/non-ablative platform | D2: Modular aesthetic laser platform (BBL+Halo+ProFractional) | E2: Sciton JOULE X / Lumenis M22 | F2: Skin resurfacing, pigment, vascular - workhorse aesthetic platform | G2: Lanserhof/CLP-tier | H2: Lanserhof/CLP-tier | I2: 180000 | J2: 215000 | K2: 175000 | L2: UAE | M2: 25000000 | N2: 1 | O2: 8 | P2: 0.1 | Q2: 0.6 | R2: Sciton dealer; pre-owned mJOULE $149,950 (mrp.io); Lumenis dealer 2024 | S2: Medium | T2: 2026-05 | U2: REGULATORY FLAG: US-OEM. Russian import via parallel channels +20-30%. Consider European alternatives (Asclepion, Quantel).
A3: 2 | B3: Aesthetic & Regenerative | C3: Cryolipolysis | D3: Cryolipolysis system (fat reduction) | E3: Allergan CoolSculpting Elite / Cooltech Define | F3: Non-invasive fat reduction - high-margin aesthetic service | G3: Optional upsell | H3: Optional upsell | I3: 100000 | J3: 120000 | K3: 95000 | L3: UAE | M3: 14000000 | N3: 1 | O3: 7 | P3: 0.1 | Q3: 0.4 | R3: Allergan dealer 2024; Offer Aesthetic refurbished CoolSculpting Elite listings | S3: Medium | T3: 2026-05 | U3: REGULATORY FLAG: Allergan/AbbVie US-controlled. Cooltech (Spain, now Cocoon Medical) preferable for Russia.
A4: 3 | B4: Aesthetic & Regenerative | C4: EMSculpt / muscle stim | D4: Electromagnetic muscle stimulation (HIFEM) | E4: BTL EMSculpt NEO | F4: Muscle building + fat reduction - popular spa add-on | G4: Lanserhof/CLP-tier | H4: SHA/Chenot-tier | I4: 130000 | J4: 150000 | K4: 125000 | L4: UAE | M4: 18000000 | N4: 1 | O4: 7 | P4: 0.1 | Q4: 0.4 | R4: BTL Industries dealer quotes 2024-25 | S4: Medium | T4: 2026-05 | U4: BTL is Czech-owned - Russia route relatively clean.
A5: 4 | B5: Aesthetic & Regenerative | C5: HIFU skin lifting | D5: Microfocused ultrasound skin lifting (HIFU) | E5: Merz Ultherapy Prime / Ulthera | F5: Non-surgical skin tightening - high demand procedure | G5: SHA/Chenot-tier | H5: SHA/Chenot-tier | I5: 65000 | J5: 75000 | K5: 60000 | L5: UAE | M5: 9000000 | N5: 1 | O5: 7 | P5: 0.12 | Q5: 0.4 | R5: konmison Ultherapy machine cost guide 2025; vsquareclinic Ulthera Prime | S5: Medium | T5: 2026-05 | U5: Cartridge consumables ~$300/treatment. Russia: Merz EU-OEM, lower sanctions risk than US.
A6: 5 | B6: Aesthetic & Regenerative | C6: LED light therapy | D6: LED light therapy bed / panel (medical) | E6: NovoTHOR / Celluma PRO panels | F6: Photobiomodulation for skin/recovery/longevity | G6: SHA/Chenot-tier | H6: SHA/Chenot-tier | I6: 65000 | J6: 78000 | K6: 60000 | L6: UAE | M6: 9000000 | N6: 1 | O6: 10 | P6: 0.04 | Q6: 0.2 | R6: NovoTHOR retail 2024 (~$70-90k); Celluma Pro $3-5k panels alt | S6: Medium | T6: 2026-05 | U6: NovoTHOR full-body bed is signature offering at premium clinics.
A7: 6 | B7: Aesthetic & Regenerative | C7: Radiofrequency therapy | D7: Radiofrequency therapy device (448 kHz Tecar) | E7: Indiba Activ Elite NS / Indiba CT9 | F7: Tissue regeneration, recovery, body contouring - rehab+aesthetic dual use | G7: SHA/Chenot-tier | H7: SHA/Chenot-tier | I7: 35000 | J7: 42000 | K7: 33000 | L7: UAE | M7: 4800000 | N7: 2 | O7: 8 | P7: 0.07 | Q7: 0.6 | R7: Indiba dealer references; NYDNRehab clinical pricing; eBay used listings ~$55k | S7: Medium | T7: 2026-05 | U7: Spanish OEM, cleaner Russia route than US lasers.
A8: 7 | B8: Aesthetic & Regenerative | C8: Vascular/pigment laser platform | D8: Multi-wavelength aesthetic laser platform (KTP+Nd:YAG) | E8: Cutera Excel V+ / Candela GentleMax Pro | F8: Vascular lesions, pigmentation, skin rejuvenation | G8: Lanserhof/CLP-tier | H8: Lanserhof/CLP-tier | I8: 90000 | J8: 105000 | K8: 85000 | L8: UAE | M8: 12500000 | N8: 1 | O8: 8 | P8: 0.1 | Q8: 0.5 | R8: The Laser Agent 2025 new Cutera Excel V+ listings, Bimedis range $18,613-$49,950 used | S8: Medium | T8: 2026-05 | U8: REGULATORY FLAG: US/Israel-OEM aesthetic lasers face Russian import constraints. Source via Turkey/UAE re-export, expect +15-25% markup and parallel-import warranty risk.
A9: 8 | B9: Body Composition & Performance | C9: Body composition - air displacement | D9: BodPod GS-X air displacement plethysmograph | E9: Cosmed BodPod GS-X | F9: Gold-standard 2-compartment body composition; differentiator vs InBody | G9: Six Senses Place-tier | H9: Lanserhof/CLP-tier | I9: 50000 | J9: 58000 | K9: 48000 | L9: UAE | M9: 6600000 | N9: 1 | O9: 12 | P9: 0.05 | Q9: 0.2 | R9: Cosmed dealer quotes, MedicalExpo 2024 | S9: Medium | T9: 2026-05 | U9: Used by Lanserhof, CLP. Heavy unit, dedicated room with stable temperature required.
A10: 9 | B10: Body Composition & Performance | C10: Body composition - bioimpedance | D10: Medical-grade body composition analyzer (BIA, multi-frequency) | E10: InBody 970 / Seca mBCA 555 (medical-grade) | F10: Segmental body composition, ECW/ICW, phase angle - foundational longevity assessment | G10: Six Senses Place-tier | H10: Lanserhof/CLP-tier | I10: 28000 | J10: 32600 | K10: 26000 | L10: UAE | M10: 3700000 | N10: 2 | O10: 8 | P10: 0.05 | Q10: 0.3 | R10: InBody USA shop list 2025 ($32,605); Seca mBCA Pro $9,599 base; HaB Direct mBCA 555 listing | S10: High | T10: 2026-05 | U10: InBody 970 is the workhorse; Seca mBCA 555 is medical-CE class. Russia: distributors in Moscow available, no sanctions issues.
A11: 10 | B11: Body Composition & Performance | C11: Cardiopulmonary | D11: VO2 max / metabolic cart (CPET) | E11: Cosmed K5 / Cosmed Quark CPET / MGC Diagnostics | F11: VO2max, RMR - central healthy-aging metric | G11: SHA/Chenot-tier | H11: Lanserhof/CLP-tier | I11: 45000 | J11: 52000 | K11: 42000 | L11: UAE | M11: 6000000 | N11: 1 | O11: 10 | P11: 0.08 | Q11: 0.4 | R11: Cosmed dealer 2024, MedicalExpo listings | S11: Medium | T11: 2026-05 | U11: Lanserhof/SHA both run CPET. Includes treadmill or cycle ergometer.
A12: 11 | B12: Body Composition & Performance | C12: DEXA scanner | D12: DEXA body composition / bone density scanner | E12: Hologic Horizon / GE Lunar iDXA | F12: Bone density + body composition gold standard | G12: SHA/Chenot-tier | H12: Lanserhof/CLP-tier | I12: 95000 | J12: 115000 | K12: 90000 | L12: UAE | M12: 13100000 | N12: 1 | O12: 12 | P12: 0.07 | Q12: 0.4 | R12: Hologic/GE dealer 2024 | S12: Medium | T12: 2026-05 | U12: May overlap with Phase 1 medical imaging - verify single source to avoid double-count.
A13: 12 | B13: Body Composition & Performance | C13: Force/gait analysis | D13: Force plate system (dual, embedded) | E13: AMTI BMS400600 / Bertec FP4060 | F13: Ground reaction force, balance, gait kinetics | G13: SHA/Chenot-tier | H13: Lanserhof/CLP-tier | I13: 45000 | J13: 52000 | K13: 42000 | L13: UAE | M13: 6000000 | N13: 1 | O13: 15 | P13: 0.04 | Q13: 0.2 | R13: AMTI dealer quotes, Noraxon partner pricing 2024 | S13: Medium | T13: 2026-05 | U13: Pair of plates; install requires recessed floor pit. Often paired with Vicon.
... A66: 65 | B66: IT, EHR, Patient Software | C66: Access control & RFID locks | D66: Electronic guest room locks + back-of-house access | E66: Salto, Assa Abloy VingCard, dormakaba | F66: RFID/mobile keys per door; staff zones | G66: Six Senses Place-tier | H66: Lanserhof/CLP-tier | I66: 165000 | J66: 200000 | K66: 130000 | L66: China | M66: 20500000 | N66: 1 | O66: 12 | P66: 0.04 | Q66: 0 | R66: Kompareit hotel access $1500-2500/door; 100 doors + 30 BoH | S66: High | T66: 2026-05 | U66: Premium spec (BLE+mobile key). Russia: VingCard via parallel import; +20-25%.
A67: 66 | B67: IT, EHR, Patient Software | C67: EHR System | D67: Mid-market EHR (Athenahealth-tier) | E67: Athenahealth athenaOne, Tebra, ModMed; Russian: МИС МедОфис, qMS | F67: Clinical record-keeping for medical center; integrates lab/imaging | G67: SHA/Chenot-tier | H67: Lanserhof/CLP-tier | I67: 180000 | J67: 220000 | K67: 150000 | L67: Singapore | M67: 12000000 | N67: 1 | O67: 7 | P67: 0 | Q67: 0.5 | R67: Athenahealth $140/provider/mo + 4-8% collections; impl $2-5k/provider; emrguides.com 2025 | S67: Medium | T67: 2026-05 | U67: Russia: 152-FZ data localization blocks Western cloud EHR. qMS/МедОфис ~50% Western cost; needs custom integration. | V67: 90000 | W67: 110000 | X67: 75000 | Y67: 6000000
A68: 67 | B68: IT, EHR, Patient Software | C68: EHR System (Optional Epic-tier) | D68: Enterprise EHR (Epic/Cerner) | E68: Epic Hyperspace, Oracle Health (Cerner Millennium) | F68: Full enterprise EHR for hospital-grade resort medical center | G68: Optional upsell | H68: Optional upsell | I68: 1800000 | J68: 2200000 | K68: 1500000 | L68: Singapore | M68: 0 | N68: 0 | O68: 10 | P68: 0 | Q68: 1 | R68: Tactionsoft 2025 ($500k-$10M); arkenea.com Cerner; Veterans Memorial Hospital $3.88M | S68: Medium | T68: 2026-05 | U68: Overkill for 80-100 keys; only relevant if hospital-grade. Not deployable in Russia. | V68: 350000 | W68: 420000 | X68: 300000 | Y68: 0
A69: 68 | B69: IT, EHR, Patient Software | C69: Guest experience / mobile app | D69: Guest mobile app + in-room tablet platform | E69: Crave Interactive, SuitePad, Hudini, INTELITY | F69: Mobile check-in, in-room ordering, treatment booking, content | G69: Six Senses Place-tier | H69: Lanserhof/CLP-tier | I69: 90000 | J69: 110000 | K69: 75000 | L69: Singapore | M69: 9500000 | N69: 1 | O69: 5 | P69: 0 | Q69: 0 | R69: Hospitality tech benchmark; tablet $600-1200/room + license $25-40/room/mo | S69: Medium | T69: 2026-05 | U69: Includes tablets per room, license, and PMS/spa integration. | V69: 35000 | W69: 42000 | X69: 28000 | Y69: 2800000
A70: 69 | B70: IT, EHR, Patient Software | C70: Longevity patient platform | D70: Longevity-specific patient/wellness platform | E70: Function Health (B2B), Hone Health, Healthspan; alt: custom | F70: Biomarker tracking, member portal, longitudinal results, AI insights | G70: Six Senses Place-tier | H70: Lanserhof/CLP-tier | I70: 75000 | J70: 90000 | K70: 65000 | L70: Singapore | M70: 8500000 | N70: 1 | O70: 5 | P70: 0 | Q70: 0.5 | R70: Function Health B2B (Equinox $249, Higginbotham $334/yr/member); sacra.com | S70: Low | T70: 2026-05 | U70: Annual = ~200-300 active members at $250-$350/yr. Russia: must build custom or isolated instance. | V70: 60000 | W70: 72000 | X70: 55000 | Y70: 4000000
A71: 70 | B71: IT, EHR, Patient Software | C71: Network infrastructure | D71: Wired + Wi-Fi 6/7 backbone (enterprise) | E71: Cisco Meraki, RUCKUS Networks, Aruba; Russian: Eltex, QTECH | F71: Guest + back-of-house network, segmented VLANs incl. medical | G71: Six Senses Place-tier | H71: Lanserhof/CLP-tier | I71: 220000 | J71: 260000 | K71: 170000 | L71: Singapore | M71: 28000000 | N71: 1 | O71: 8 | P71: 0.1 | Q71: 0 | R71: RUCKUS/Cisco hospitality vertical; ~EUR 2-3k per AP installed, 80 APs + switching | S71: Medium | T71: 2026-05 | U71: Russia: Cisco/Aruba sanctioned post-2022. Eltex/QTECH or grey-market.
A72: 71 | B72: IT, EHR, Patient Software | C72: PMS - Hotel side | D72: Cloud PMS (luxury 80-100 keys) | E72: Mews Enterprise, Oracle Opera Cloud, Protel; Russian: Bnovo, Shelter, TravelLine | F72: Reservations, guest folio, housekeeping, channel mgmt, POS integration | G72: Six Senses Place-tier | H72: Lanserhof/CLP-tier | I72: 45000 | J72: 55000 | K72: 38000 | L72: Singapore | M72: 2500000 | N72: 1 | O72: 7 | P72: 0 | Q72: 0 | R72: Mews Enterprise tier (hoteltechreport, roommaster); Mews EUR 300/mo standalone reference | S72: Medium | T72: 2026-05 | U72: Russia 2026: Mews/Opera withdrew post-2022 sanctions. Russian alts (Shelter, Bnovo) ~50-60% cost but limited luxury feature parity. | V72: 36000 | W72: 45000 | X72: 32000 | Y72: 1500000
A73: 72 | B73: IT, EHR, Patient Software | C73: Security - cameras | D73: IP CCTV system (40-60 cameras + NVR) | E73: Avigilon, Axis, Hanwha; Russian: TRASSIR, Macroscop | F73: Perimeter + back-of-house security | G73: Six Senses Place-tier | H73: Lanserhof/CLP-tier | I73: 75000 | J73: 90000 | K73: 55000 | L73: China | M73: 7800000 | N73: 1 | O73: 10 | P73: 0.05 | Q73: 0 | R73: Avigilon/Axis dealer; ~EUR 1-1.5k per camera installed | S73: High | T73: 2026-05 | U73: Russia: TRASSIR dominant local; pricing favorable vs Western.
A74: 73 | B74: IT, EHR, Patient Software | C74: Spa/medical booking system | D74: Integrated spa & treatment booking | E74: Book4Time, Agilysys Spa, ResortSuite | F74: Therapist scheduling, room utilization, package mgmt, retail | G74: Six Senses Place-tier | H74: Lanserhof/CLP-tier | I74: 55000 | J74: 68000 | K74: 45000 | L74: Singapore | M74: 3500000 | N74: 1 | O74: 7 | P74: 0 | Q74: 0 | R74: Book4Time/Agilysys/ResortSuite indicative dealer 2025 | S74: Medium | T74: 2026-05 | U74: Critical at premium wellness resorts; integrates with PMS and EHR. | V74: 28000 | W74: 35000 | X74: 22000 | Y74: 1500000
A75: 74 | B75: IT, EHR, Patient Software | C75: Telephony / IPTV | D75: VoIP telephony + IPTV system | E75: Mitel, Cisco; LG/Samsung Pro:Idiom IPTV | F75: In-room phone, IPTV, BoH telephony | G75: Six Senses Place-tier | H75: Lanserhof/CLP-tier | I75: 95000 | J75: 115000 | K75: 75000 | L75: China | M75: 12500000 | N75: 1 | O75: 10 | P75: 0.06 | Q75: 0 | R75: Hospitality AV/IT integrator benchmark | S75: Medium | T75: 2026-05 | U75: Mid-tier resorts may go phone-light/streaming-only.
A76: 75 | B76: IV & Infusion | C76: Hyperbaric | D76: Hyperbaric oxygen chamber - mild HBOT (1.3-1.5 ATA) | E76: OxyHealth Vitaeris 320, Hyperbaric Centrales OxyVita, Summit to Sea Dive | F76: Soft-shell mild hyperbaric oxygen therapy for recovery / longevity protocols. | G76: Lanserhof/CLP-tier | H76: Lanserhof/CLP-tier | I76: 35000 | J76: 40000 | K76: 28000 | L76: China | M76: 4800000 | N76: 2 | O76: 10 | P76: 0.05 | Q76: 0.5 | R76: OxyHealth Vitaeris 320 dealer list $20-35k; soft-shell mild HBOT typical EUR 25-45k. Hard-shell medical-grade chambers (2.0+ ATA) are 5-10x more. | S76: Medium | T76: 2026-05 | U76: Soft-shell mild HBOT scope (regulatory simpler, no pressurised oxygen). Hard-shell HBOT excluded - different category. Russia: domestic BLKS chambers and OxyHealth via parallel import.
A77: 76 | B77: IV & Infusion | C77: IHHT | D77: IHHT intermittent hypoxic-hyperoxic training device | E77: Cellgym Pro / Lounge, Hypoxico Everest Summit II, GO2Altitude Biomedtech | F77: Intermittent hypoxia-hyperoxia therapy - mitochondrial training, longevity protocol. | G77: Lanserhof/CLP-tier | H77: Lanserhof/CLP-tier | I77: 35000 | J77: 40000 | K77: 28000 | L77: China | M77: 4800000 | N77: 3 | O77: 8 | P77: 0.05 | Q77: 0.3 | R77: Cellgym dealer quotes EUR 30-45k for Pro/Lounge unit; Hypoxico distributor pricing; Cocoon Medical Spa public Cellgym installation references. | S77: Low | T77: 2026-05 | U77: ESTIMATE - Cellgym list price not public. Per-session retail EUR 50-80 cited. 3 units cover 25-30 sessions/day. Russia: Russian-developed Bio-Nova MTI/IHT is domestic alternative at EUR 12-18k.
A78: 77 | B78: IV & Infusion | C78: IV Suite | D78: IV therapy lounge chair (clinical recliner) | E78: Champion Manufacturing 56 series, Stance Healthcare Bari, Winco CareCliner | F78: Comfortable reclining infusion chair for IV drips / NAD+ / vitamin therapy lounge. | G78: SHA/Chenot-tier | H78: Lanserhof/CLP-tier | I78: 3500 | J78: 4000 | K78: 2500 | L78: China | M78: 480000 | N78: 6 | O78: 10 | P78: 0.04 | Q78: 0 | R78: Champion / Stance / Winco published dealer pricing $2,500-$5,000 per clinical recliner; common dealer quote EUR 3,000-4,500. | S78: High | T78: 2026-05 | U78: 6-8 chairs for an 80-100 key longevity resort IV lounge. Russia: domestic Med-Mos and import via Turkey both feasible.
A79: 78 | B79: IV & Infusion | C79: Infusion Pumps | D79: Smart infusion pump | E79: B.Braun Infusomat Space, Baxter Sigma Spectrum IQ, BD Alaris | F79: Smart infusion pump with DERS for IV vitamins, NAD+, chelation, peptides. | G79: SHA/Chenot-tier | H79: Lanserhof/CLP-tier | I79: 3500 | J79: 4000 | K79: 2500 | L79: China | M79: 480000 | N79: 8 | O79: 7 | P79: 0.06 | Q79: 0 | R79: Outfront Medical / Coast Biomed Baxter Sigma Spectrum refurb $1.5-2.5k; B.Braun new ~EUR 3-4k list. | S79: High | T79: 2026-05 | U79: 8 pumps to cover 6-chair IV lounge + 2 spares. Russia: B.Braun (German) still distributed but wait times extended; Russian Yelatma pumps also used.
A80: 79 | B80: IV & Infusion | C80: Ozone Therapy | D80: Medical ozone therapy generator | E80: Herrmann Apparatebau Hyper Medozon comfort, Zotzmann + Stahl OzonoSan, Humares Medozon | F80: Major/minor autohemotherapy, ozone insufflation, ozonated saline. | G80: Lanserhof/CLP-tier | H80: Lanserhof/CLP-tier | I80: 18000 | J80: 0 | K80: 14000 | L80: China | M80: 2500000 | N80: 2 | O80: 10 | P80: 0.05 | Q80: 0.3 | R80: MedicalExpo Herrmann Hyper Medozon comfort; HealthManagement.org Hyper Medozon comfort listing; secondary market Medbidding refurb 6-9k EUR; new list EUR 15-22k from German dealers. | S80: Medium | T80: 2026-05 | U80: Heavily regulated - banned/restricted in US (FDA), allowed in Germany/Austria/CH/Spain/Russia under medical supervision. Russia: ozone therapy is well-established (Russian Federal MoH-registered indications); Russian Medozons-BM domestic alternative.
A81: 80 | B81: Kitchen & F&B | C81: Bakery oven | D81: Deck/convection bakery oven | E81: MIWE Condo 3.0608, MIWE econo, Wachtel | F81: In-house bread, pastry, gluten-free baking | G81: Six Senses Place-tier | H81: Lanserhof/CLP-tier | I81: 42000 | J81: 52000 | K81: 38000 | L81: China | M81: 5300000 | N81: 1 | O81: 15 | P81: 0.04 | Q81: 0 | R81: MIWE/Wachtel dealer indicative (archiexpo, bakeryequipment.com); 3-deck unit | S81: Medium | T81: 2026-05 | U81: Lanserhof-style organic/gluten-free bakery requires deck oven + proofer.
A82: 81 | B82: Kitchen & F&B | C82: Cold kitchen / garde manger | D82: Cold kitchen station (refrigerated prep + plating) | E82: Inomak, True, Hoshizaki | F82: Salads, raw, sashimi, plating for clean cuisine | G82: Six Senses Place-tier | H82: SHA/Chenot-tier | I82: 35000 | J82: 42000 | K82: 28000 | L82: China | M82: 4400000 | N82: 1 | O82: 12 | P82: 0.04 | Q82: 0 | R82: Inomak/True dealer EU; 6-8 m linear cold prep + worktops | S82: Medium | T82: 2026-05 | U82: Critical for raw/clean cuisine programs (Chenot-style).
A83: 82 | B83: Kitchen & F&B | C83: Combi oven | D83: Premium combi oven (10-grid 1/1) | E83: Rational iCombi Pro 10-1/1, Convotherm 4 easyTouch | F83: Therapeutic + restaurant cooking; steam, convection, low-temp | G83: Six Senses Place-tier | H83: Lanserhof/CLP-tier | I83: 22000 | J83: 27000 | K83: 19000 | L83: China | M83: 2750000 | N83: 3 | O83: 12 | P83: 0.05 | Q83: 0 | R83: Rational dealer indicative (WebstaurantStore, Buzz Catering, Nella) 2025; Russian dealer markup ~1.25x EU | S83: High | T83: 2026-05 | U83: Three units cover therapeutic, hot kitchen, and banqueting.
A84: 83 | B84: Kitchen & F&B | C84: Combi oven (small) | D84: Compact combi oven (6-grid 1/1) | E84: Rational iCombi Pro 6-1/1, UNOX ChefTop | F84: Pastry, fish, dietary station, room service line | G84: Six Senses Place-tier | H84: SHA/Chenot-tier | I84: 14500 | J84: 18000 | K84: 12000 | L84: China | M84: 1800000 | N84: 2 | O84: 12 | P84: 0.05 | Q84: 0 | R84: Rational price list indicative; UNOX dealer EU 2025 | S84: High | T84: 2026-05 | U84: Used for pastry/cold-finishing kitchen and dietary line.
A85: 84 | B85: Kitchen & F&B | C85: Dishwasher (flight/conveyor) | D85: Conveyor/flight dishwasher | E85: Hobart FT1000e, Winterhalter MTF, Meiko M-iQ | F85: Main banquet/restaurant dish line | G85: Six Senses Place-tier | H85: Lanserhof/CLP-tier | I85: 75000 | J85: 90000 | K85: 60000 | L85: China | M85: 9500000 | N85: 1 | O85: 12 | P85: 0.05 | Q85: 0 | R85: Hobart, Winterhalter dealer EU 2025; hobartcorp.com | S85: High | T85: 2026-05 | U85: Required at 80-100 keys for banquet capacity.
A86: 85 | B86: Kitchen & F&B | C86: Dishwasher (under-counter & pass-through) | D86: Pass-through and undercounter glasswashers/dishwashers (set) | E86: Hobart, Winterhalter UC-M, Meiko | F86: Bar, juice bar, prep stations | G86: Six Senses Place-tier | H86: Lanserhof/CLP-tier | I86: 28000 | J86: 34000 | K86: 22000 | L86: China | M86: 3500000 | N86: 4 | O86: 10 | P86: 0.05 | Q86: 0 | R86: Hobart/Winterhalter dealer EU 2025 | S86: High | T86: 2026-05 | U86: Set of 4 covers bar, juice bar, banqueting, satellite.
... A130: 129 | B130: Sleep & Neurology | C130: Wearables | D130: Premium wearables (Oura / WHOOP / Apple Watch fleet for guests) | E130: Oura Ring Gen 4, WHOOP 5.0, Apple Watch Ultra 2 | F130: Sleep stages, HRV, recovery, training load - guest take-home wearable as part of programme. | G130: SHA/Chenot-tier | H130: Lanserhof/CLP-tier | I130: 8000 | J130: 9000 | K130: 6500 | L130: China | M130: 1100000 | N130: 25 | O130: 3 | P130: 0.1 | Q130: 0 | R130: Oura Ring $349-$499 retail; WHOOP $239 + $30/mo subscription; Apple Watch Ultra 2 $799. 25-unit fleet at avg EUR 320 per device. | S130: High | T130: 2026-05 | U130: Loaner fleet for in-residence guests. Subscription costs flow as OPEX. Russia: Apple Watch / Oura via parallel import (30% premium); WHOOP not available officially.
A131: 130 | B131: Telemedicine & Digital Health | C131: CGM data integration | D131: CGM platform integration (Levels-style) | E131: Levels Health API, Nutrisense, Veri | F131: Continuous glucose monitor data into longevity platform | G131: Six Senses Place-tier | H131: SHA/Chenot-tier | I131: 18000 | J131: 22000 | K131: 15000 | L131: Singapore | M131: 2200000 | N131: 1 | O131: 5 | P131: 0 | Q131: 0 | R131: Levels API B2B / Nutrisense partner; partner integration estimate | S131: Low | T131: 2026-05 | U131: Sensors charged per guest separately. Russia: Abbott Libre via parallel import; Russian dev for portal. | V131: 14000 | W131: 17000 | X131: 11000 | Y131: 1400000
A132: 131 | B132: Telemedicine & Digital Health | C132: Post-stay coaching platform | D132: Coaching/concierge app (post-stay continuum) | E132: MindBody Plus, Healthie, custom on Twilio | F132: 1:1 coaching, content, member retention 6-12 months post-stay | G132: Six Senses Place-tier | H132: Lanserhof/CLP-tier | I132: 65000 | J132: 80000 | K132: 55000 | L132: Singapore | M132: 7500000 | N132: 1 | O132: 5 | P132: 0 | Q132: 1 | R132: Healthie / custom dev estimate; Lanserhof@home model reference | S132: Low | T132: 2026-05 | U132: Critical revenue/retention driver - drives ARR via subscription. Operator headcount = coaches. | V132: 30000 | W132: 38000 | X132: 24000 | Y132: 2400000
A133: 132 | B133: Telemedicine & Digital Health | C133: Video consultation platform | D133: HIPAA/GDPR-compliant telemedicine platform | E133: Doxy.me Enterprise, Teladoc B2B, Amwell | F133: Post-stay video consults with longevity physicians | G133: Six Senses Place-tier | H133: Lanserhof/CLP-tier | I133: 25000 | J133: 32000 | K133: 22000 | L133: Singapore | M133: 2500000 | N133: 1 | O133: 5 | P133: 0 | Q133: 0 | R133: Doxy.me Clinic $50/user/mo; Enterprise custom; ~30-40 users | S133: High | T133: 2026-05 | U133: Russia: Russian alt (Mednote, Doctis) due to GDPR/152-FZ + sanctions. | V133: 22000 | W133: 28000 | X133: 18000 | Y133: 1800000
A134: 133 | B134: Telemedicine & Digital Health | C134: Wearable program - WHOOP/Garmin | D134: WHOOP Unite + Garmin Health enterprise | E134: WHOOP Unite, Garmin Health enterprise | F134: Strain/recovery tracking, performance/longevity coaching | G134: Optional upsell | H134: Optional upsell | I134: 35000 | J134: 42000 | K134: 28000 | L134: Singapore | M134: 4200000 | N134: 1 | O134: 4 | P134: 0 | Q134: 0 | R134: WHOOP Unite (200+ enterprise customers, prnewswire 2022); Garmin Health B2B | S134: Low | T134: 2026-05 | U134: Optional supplement to Oura. Russia: parallel import for hardware. | V134: 25000 | W134: 30000 | X134: 20000 | Y134: 2400000
A135: 134 | B135: Telemedicine & Digital Health | C135: Wearable program - rings | D135: Oura Ring Business deployment | E135: Oura for Business, Ultrahuman Ring, RingConn | F135: Member sleep/HRV/recovery tracking; lifelong engagement hook | G135: Six Senses Place-tier | H135: Lanserhof/CLP-tier | I135: 65000 | J135: 80000 | K135: 55000 | L135: Singapore | M135: 7500000 | N135: 1 | O135: 4 | P135: 0 | Q135: 0 | R135: Oura for Business B2B (sacra.com 23% revenue); ~200 rings @ $300 + dashboard | S135: Medium | T135: 2026-05 | U135: Initial fleet 150-250 rings + B2B dashboard; replenishment ~25%/yr. | V135: 18000 | W135: 22000 | X135: 14000 | Y135: 1800000

Sheet Capex Summary by Tier
A1: CAPEX SUMMARY BY TIER
A2: Live roll-up from Master List via SUMPRODUCT. Edit prices in Master List → totals refresh.
A3: keys_count | B3: 90 | C3: ← editable input (mid-point of 80–100 keys range)
A4: FX RUB / EUR | B4: 92
A5: FX RUB / USD | B5: 85
A7: REGION — Europe (€)
A8: Group | B8: Lanserhof/CLP-tier | C8: SHA/Chenot-tier | D8: Six Senses Place-tier
A9: Total Medical capex | B9: =SUMPRODUCT((((1*('Equipment Master List'!$G$2:$G$135="Six Senses Place-tier")+2*('Equipment Master List'!$G$2:$G$135="SHA/Chenot-tier")+3*('Equipment Master List'!$G$2:$G$135="Lanserhof/CLP-tier"))>0)*((1*('Equipment Master List'!$G$2:$G$135="Six Senses Place-tier")+2*('Equipment Master List'!$G$2:$G$135="SHA/Chenot-tier")+3*('Equipment Master List'!$G$2:$G$135="Lanserhof/CLP-tier"))<=3))*(('Equipment Master List'!$B$2:$B$135="Diagnostic Imaging")+('Equipment Master List'!$B$2:$B$135="Laboratory & Biomarkers")+('Equipment Master List'!$B$2:$B$135="Cardiology & Pulmonology")+('Equipment Master List'!$B$2:$B$135="Sleep & Neurology")+('Equipment Master List'!$B$2:$B$135="IV & Infusion")+('Equipment Master List'!$B$2:$B$135="Aesthetic & Regenerative")+('Equipment Master List'!$B$2:$B$135="Nutrition & GI Diagnostics")+('Equipment Master List'!$B$2:$B$135="Body Composition & Performance")+('Equipment Master List'!$B$2:$B$135="Telemedicine & Digital Health"))*IFERROR('Equipment Master List'!$N$2:$N$135+0,0)*IFERROR('Equipment Master List'!$I$2:$I$135+0,0)) -> 7636500 | C9: =SUMPRODUCT((((1*('Equipment Master List'!$G$2:$G$135="Six Senses Place-tier")+2*('Equipment Master List'!$G$2:$G$135="SHA/Chenot-tier")+3*('Equipment Master List'!$G$2:$G$135="Lanserhof/CLP-tier"))>0)*((1*('Equipment Master List'!$G$2:$G$135="Six Senses Place-tier")+2*('Equipment Master List'!$G$2:$G$135="SHA/Chenot-tier")+3*('Equipment Master List'!$G$2:$G$135="Lanserhof/CLP-tier"))<=2))*(('Equipment Master List'!$B$2:$B$135="Diagnostic Imaging")+('Equipment Master List'!$B$2:$B$135="Laboratory & Biomarkers")+('Equipment Master List'!$B$2:$B$135="Cardiology & Pulmonology")+('Equipment Master List'!$B$2:$B$135="Sleep & Neurology")+('Equipment Master List'!$B$2:$B$135="IV & Infusion")+('Equipment Master List'!$B$2:$B$135="Aesthetic & Regenerative")+('Equipment Master List'!$B$2:$B$135="Nutrition & GI Diagnostics")+('Equipment Master List'!$B$2:$B$135="Body Composition & Performance")+('Equipment Master List'!$B$2:$B$135="Telemedicine & Digital Health"))*IFERROR('Equipment Master List'!$N$2:$N$135+0,0)*IFERROR('Equipment Master List'!$I$2:$I$135+0,0)) -> 2222500 | D9: =SUMPRODUCT((((1*('Equipment Master List'!$G$2:$G$135="Six Senses Place-tier")+2*('Equipment Master List'!$G$2:$G$135="SHA/Chenot-tier")+3*('Equipment Master List'!$G$2:$G$135="Lanserhof/CLP-tier"))>0)*((1*('Equipment Master List'!$G$2:$G$135="Six Senses Place-tier")+2*('Equipment Master List'!$G$2:$G$135="SHA/Chenot-tier")+3*('Equipment Master List'!$G$2:$G$135="Lanserhof/CLP-tier"))<=1))*(('Equipment Master List'!$B$2:$B$135="Diagnostic Imaging")+('Equipment Master List'!$B$2:$B$135="Laboratory & Biomarkers")+('Equipment Master List'!$B$2:$B$135="Cardiology & Pulmonology")+('Equipment Master List'!$B$2:$B$135="Sleep & Neurology")+('Equipment Master List'!$B$2:$B$135="IV & Infusion")+('Equipment Master List'!$B$2:$B$135="Aesthetic & Regenerative")+('Equipment Master List'!$B$2:$B$135="Nutrition & GI Diagnostics")+('Equipment Master List'!$B$2:$B$135="Body Composition & Performance")+('Equipment Master List'!$B$2:$B$135="Telemedicine & Digital Health"))*IFERROR('Equipment Master List'!$N$2:$N$135+0,0)*IFERROR('Equipment Master List'!$I$2:$I$135+0,0)) -> 279000
A10: Total Spa & Recovery capex | B10: =SUMPRODUCT((((1*('Equipment Master List'!$G$2:$G$135="Six Senses Place-tier")+2*('Equipment Master List'!$G$2:$G$135="SHA/Chenot-tier")+3*('Equipment Master List'!$G$2:$G$135="Lanserhof/CLP-tier"))>0)*((1*('Equipment Master List'!$G$2:$G$135="Six Senses Place-tier")+2*('Equipment Master List'!$G$2:$G$135="SHA/Chenot-tier")+3*('Equipment Master List'!$G$2:$G$135="Lanserhof/CLP-tier"))<=3))*(('Equipment Master List'!$B$2:$B$135="Hydrotherapy & Spa")+('Equipment Master List'!$B$2:$B$135="Cryo & Thermal"))*IFERROR('Equipment Master List'!$N$2:$N$135+0,0)*IFERROR('Equipment Master List'!$I$2:$I$135+0,0)) -> 1626000 | C10: =SUMPRODUCT((((1*('Equipment Master List'!$G$2:$G$135="Six Senses Place-tier")+2*('Equipment Master List'!$G$2:$G$135="SHA/Chenot-tier")+3*('Equipment Master List'!$G$2:$G$135="Lanserhof/CLP-tier"))>0)*((1*('Equipment Master List'!$G$2:$G$135="Six Senses Place-tier")+2*('Equipment Master List'!$G$2:$G$135="SHA/Chenot-tier")+3*('Equipment Master List'!$G$2:$G$135="Lanserhof/CLP-tier"))<=2))*(('Equipment Master List'!$B$2:$B$135="Hydrotherapy & Spa")+('Equipment Master List'!$B$2:$B$135="Cryo & Thermal"))*IFERROR('Equipment Master List'!$N$2:$N$135+0,0)*IFERROR('Equipment Master List'!$I$2:$I$135+0,0)) -> 1626000 | D10: =SUMPRODUCT((((1*('Equipment Master List'!$G$2:$G$135="Six Senses Place-tier")+2*('Equipment Master List'!$G$2:$G$135="SHA/Chenot-tier")+3*('Equipment Master List'!$G$2:$G$135="Lanserhof/CLP-tier"))>0)*((1*('Equipment Master List'!$G$2:$G$135="Six Senses Place-tier")+2*('Equipment Master List'!$G$2:$G$135="SHA/Chenot-tier")+3*('Equipment Master List'!$G$2:$G$135="Lanserhof/CLP-tier"))<=1))*(('Equipment Master List'!$B$2:$B$135="Hydrotherapy & Spa")+('Equipment Master List'!$B$2:$B$135="Cryo & Thermal"))*IFERROR('Equipment Master List'!$N$2:$N$135+0,0)*IFERROR('Equipment Master List'!$I$2:$I$135+0,0)) -> 1626000
A11: Total Fitness & Movement capex | B11: =SUMPRODUCT((((1*('Equipment Master List'!$G$2:$G$135="Six Senses Place-tier")+2*('Equipment Master List'!$G$2:$G$135="SHA/Chenot-tier")+3*('Equipment Master List'!$G$2:$G$135="Lanserhof/CLP-tier"))>0)*((1*('Equipment Master List'!$G$2:$G$135="Six Senses Place-tier")+2*('Equipment Master List'!$G$2:$G$135="SHA/Chenot-tier")+3*('Equipment Master List'!$G$2:$G$135="Lanserhof/CLP-tier"))<=3))*(('Equipment Master List'!$B$2:$B$135="Movement & Rehab")+('Equipment Master List'!$B$2:$B$135="Gym & Strength"))*IFERROR('Equipment Master List'!$N$2:$N$135+0,0)*IFERROR('Equipment Master List'!$I$2:$I$135+0,0)) -> 1335000 | C11: =SUMPRODUCT((((1*('Equipment Master List'!$G$2:$G$135="Six Senses Place-tier")+2*('Equipment Master List'!$G$2:$G$135="SHA/Chenot-tier")+3*('Equipment Master List'!$G$2:$G$135="Lanserhof/CLP-tier"))>0)*((1*('Equipment Master List'!$G$2:$G$135="Six Senses Place-tier")+2*('Equipment Master List'!$G$2:$G$135="SHA/Chenot-tier")+3*('Equipment Master List'!$G$2:$G$135="Lanserhof/CLP-tier"))<=2))*(('Equipment Master List'!$B$2:$B$135="Movement & Rehab")+('Equipment Master List'!$B$2:$B$135="Gym & Strength"))*IFERROR('Equipment Master List'!$N$2:$N$135+0,0)*IFERROR('Equipment Master List'!$I$2:$I$135+0,0)) -> 581000 | D11: =SUMPRODUCT((((1*('Equipment Master List'!$G$2:$G$135="Six Senses Place-tier")+2*('Equipment Master List'!$G$2:$G$135="SHA/Chenot-tier")+3*('Equipment Master List'!$G$2:$G$135="Lanserhof/CLP-tier"))>0)*((1*('Equipment Master List'!$G$2:$G$135="Six Senses Place-tier")+2*('Equipment Master List'!$G$2:$G$135="SHA/Chenot-tier")+3*('Equipment Master List'!$G$2:$G$135="Lanserhof/CLP-tier"))<=1))*(('Equipment Master List'!$B$2:$B$135="Movement & Rehab")+('Equipment Master List'!$B$2:$B$135="Gym & Strength"))*IFERROR('Equipment Master List'!$N$2:$N$135+0,0)*IFERROR('Equipment Master List'!$I$2:$I$135+0,0)) -> 581000
A12: Total IT & Software capex (upfront) | B12: =SUMPRODUCT((((1*('Equipment Master List'!$G$2:$G$135="Six Senses Place-tier")+2*('Equipment Master List'!$G$2:$G$135="SHA/Chenot-tier")+3*('Equipment Master List'!$G$2:$G$135="Lanserhof/CLP-tier"))>0)*((1*('Equipment Master List'!$G$2:$G$135="Six Senses Place-tier")+2*('Equipment Master List'!$G$2:$G$135="SHA/Chenot-tier")+3*('Equipment Master List'!$G$2:$G$135="Lanserhof/CLP-tier"))<=3))*(('Equipment Master List'!$B$2:$B$135="IT, EHR, Patient Software"))*IFERROR('Equipment Master List'!$N$2:$N$135+0,0)*IFERROR('Equipment Master List'!$I$2:$I$135+0,0)) -> 1000000 | C12: =SUMPRODUCT((((1*('Equipment Master List'!$G$2:$G$135="Six Senses Place-tier")+2*('Equipment Master List'!$G$2:$G$135="SHA/Chenot-tier")+3*('Equipment Master List'!$G$2:$G$135="Lanserhof/CLP-tier"))>0)*((1*('Equipment Master List'!$G$2:$G$135="Six Senses Place-tier")+2*('Equipment Master List'!$G$2:$G$135="SHA/Chenot-tier")+3*('Equipment Master List'!$G$2:$G$135="Lanserhof/CLP-tier"))<=2))*(('Equipment Master List'!$B$2:$B$135="IT, EHR, Patient Software"))*IFERROR('Equipment Master List'!$N$2:$N$135+0,0)*IFERROR('Equipment Master List'!$I$2:$I$135+0,0)) -> 1000000 | D12: =SUMPRODUCT((((1*('Equipment Master List'!$G$2:$G$135="Six Senses Place-tier")+2*('Equipment Master List'!$G$2:$G$135="SHA/Chenot-tier")+3*('Equipment Master List'!$G$2:$G$135="Lanserhof/CLP-tier"))>0)*((1*('Equipment Master List'!$G$2:$G$135="Six Senses Place-tier")+2*('Equipment Master List'!$G$2:$G$135="SHA/Chenot-tier")+3*('Equipment Master List'!$G$2:$G$135="Lanserhof/CLP-tier"))<=1))*(('Equipment Master List'!$B$2:$B$135="IT, EHR, Patient Software"))*IFERROR('Equipment Master List'!$N$2:$N$135+0,0)*IFERROR('Equipment Master List'!$I$2:$I$135+0,0)) -> 820000
A13: Total Kitchen & F&B capex | B13: =SUMPRODUCT((((1*('Equipment Master List'!$G$2:$G$135="Six Senses Place-tier")+2*('Equipment Master List'!$G$2:$G$135="SHA/Chenot-tier")+3*('Equipment Master List'!$G$2:$G$135="Lanserhof/CLP-tier"))>0)*((1*('Equipment Master List'!$G$2:$G$135="Six Senses Place-tier")+2*('Equipment Master List'!$G$2:$G$135="SHA/Chenot-tier")+3*('Equipment Master List'!$G$2:$G$135="Lanserhof/CLP-tier"))<=3))*(('Equipment Master List'!$B$2:$B$135="Kitchen & F&B"))*IFERROR('Equipment Master List'!$N$2:$N$135+0,0)*IFERROR('Equipment Master List'!$I$2:$I$135+0,0)) -> 1056000 | C13: =SUMPRODUCT((((1*('Equipment Master List'!$G$2:$G$135="Six Senses Place-tier")+2*('Equipment Master List'!$G$2:$G$135="SHA/Chenot-tier")+3*('Equipment Master List'!$G$2:$G$135="Lanserhof/CLP-tier"))>0)*((1*('Equipment Master List'!$G$2:$G$135="Six Senses Place-tier")+2*('Equipment Master List'!$G$2:$G$135="SHA/Chenot-tier")+3*('Equipment Master List'!$G$2:$G$135="Lanserhof/CLP-tier"))<=2))*(('Equipment Master List'!$B$2:$B$135="Kitchen & F&B"))*IFERROR('Equipment Master List'!$N$2:$N$135+0,0)*IFERROR('Equipment Master List'!$I$2:$I$135+0,0)) -> 1056000 | D13: =SUMPRODUCT((((1*('Equipment Master List'!$G$2:$G$135="Six Senses Place-tier")+2*('Equipment Master List'!$G$2:$G$135="SHA/Chenot-tier")+3*('Equipment Master List'!$G$2:$G$135="Lanserhof/CLP-tier"))>0)*((1*('Equipment Master List'!$G$2:$G$135="Six Senses Place-tier")+2*('Equipment Master List'!$G$2:$G$135="SHA/Chenot-tier")+3*('Equipment Master List'!$G$2:$G$135="Lanserhof/CLP-tier"))<=1))*(('Equipment Master List'!$B$2:$B$135="Kitchen & F&B"))*IFERROR('Equipment Master List'!$N$2:$N$135+0,0)*IFERROR('Equipment Master List'!$I$2:$I$135+0,0)) -> 1056000
A14: Total Medical Infrastructure capex | B14: =SUMPRODUCT((((1*('Equipment Master List'!$G$2:$G$135="Six Senses Place-tier")+2*('Equipment Master List'!$G$2:$G$135="SHA/Chenot-tier")+3*('Equipment Master List'!$G$2:$G$135="Lanserhof/CLP-tier"))>0)*((1*('Equipment Master List'!$G$2:$G$135="Six Senses Place-tier")+2*('Equipment Master List'!$G$2:$G$135="SHA/Chenot-tier")+3*('Equipment Master List'!$G$2:$G$135="Lanserhof/CLP-tier"))<=3))*(('Equipment Master List'!$B$2:$B$135="Medical Infrastructure"))*IFERROR('Equipment Master List'!$N$2:$N$135+0,0)*IFERROR('Equipment Master List'!$I$2:$I$135+0,0)) -> 1077000 | C14: =SUMPRODUCT((((1*('Equipment Master List'!$G$2:$G$135="Six Senses Place-tier")+2*('Equipment Master List'!$G$2:$G$135="SHA/Chenot-tier")+3*('Equipment Master List'!$G$2:$G$135="Lanserhof/CLP-tier"))>0)*((1*('Equipment Master List'!$G$2:$G$135="Six Senses Place-tier")+2*('Equipment Master List'!$G$2:$G$135="SHA/Chenot-tier")+3*('Equipment Master List'!$G$2:$G$135="Lanserhof/CLP-tier"))<=2))*(('Equipment Master List'!$B$2:$B$135="Medical Infrastructure"))*IFERROR('Equipment Master List'!$N$2:$N$135+0,0)*IFERROR('Equipment Master List'!$I$2:$I$135+0,0)) -> 127000 | D14: =SUMPRODUCT((((1*('Equipment Master List'!$G$2:$G$135="Six Senses Place-tier")+2*('Equipment Master List'!$G$2:$G$135="SHA/Chenot-tier")+3*('Equipment Master List'!$G$2:$G$135="Lanserhof/CLP-tier"))>0)*((1*('Equipment Master List'!$G$2:$G$135="Six Senses Place-tier")+2*('Equipment Master List'!$G$2:$G$135="SHA/Chenot-tier")+3*('Equipment Master List'!$G$2:$G$135="Lanserhof/CLP-tier"))<=1))*(('Equipment Master List'!$B$2:$B$135="Medical Infrastructure"))*IFERROR('Equipment Master List'!$N$2:$N$135+0,0)*IFERROR('Equipment Master List'!$I$2:$I$135+0,0)) -> 0
A15: TOTAL CAPEX | B15: =SUM(B9:B14) -> 13730500 | C15: =SUM(C9:C14) -> 6612500 | D15: =SUM(D9:D14) -> 4362000
A16: Capex per key | B16: =B15/$B$3 -> 152561.11 | C16: =C15/$B$3 -> 73472.222 | D16: =D15/$B$3 -> 48466.667
A18: REGION — North America ($)
A19: Group | B19: Lanserhof/CLP-tier | C19: SHA/Chenot-tier | D19: Six Senses Place-tier
A20: Total Medical capex | B20: =SUMPRODUCT((((1*('Equipment Master List'!$G$2:$G$135="Six Senses Place-tier")+2*('Equipment Master List'!$G$2:$G$135="SHA/Chenot-tier")+3*('Equipment Master List'!$G$2:$G$135="Lanserhof/CLP-tier"))>0)*((1*('Equipment Master List'!$G$2:$G$135="Six Senses Place-tier")+2*('Equipment Master List'!$G$2:$G$135="SHA/Chenot-tier")+3*('Equipment Master List'!$G$2:$G$135="Lanserhof/CLP-tier"))<=3))*(('Equipment Master List'!$B$2:$B$135="Diagnostic Imaging")+('Equipment Master List'!$B$2:$B$135="Laboratory & Biomarkers")+('Equipment Master List'!$B$2:$B$135="Cardiology & Pulmonology")+('Equipment Master List'!$B$2:$B$135="Sleep & Neurology")+('Equipment Master List'!$B$2:$B$135="IV & Infusion")+('Equipment Master List'!$B$2:$B$135="Aesthetic & Regenerative")+('Equipment Master List'!$B$2:$B$135="Nutrition & GI Diagnostics")+('Equipment Master List'!$B$2:$B$135="Body Composition & Performance")+('Equipment Master List'!$B$2:$B$135="Telemedicine & Digital Health"))*IFERROR('Equipment Master List'!$N$2:$N$135+0,0)*IFERROR('Equipment Master List'!$J$2:$J$135+0,0)) -> 8738700 | C20: =SUMPRODUCT((((1*('Equipment Master List'!$G$2:$G$135="Six Senses Place-tier")+2*('Equipment Master List'!$G$2:$G$135="SHA/Chenot-tier")+3*('Equipment Master List'!$G$2:$G$135="Lanserhof/CLP-tier"))>0)*((1*('Equipment Master List'!$G$2:$G$135="Six Senses Place-tier")+2*('Equipment Master List'!$G$2:$G$135="SHA/Chenot-tier")+3*('Equipment Master List'!$G$2:$G$135="Lanserhof/CLP-tier"))<=2))*(('Equipment Master List'!$B$2:$B$135="Diagnostic Imaging")+('Equipment Master List'!$B$2:$B$135="Laboratory & Biomarkers")+('Equipment Master List'!$B$2:$B$135="Cardiology & Pulmonology")+('Equipment Master List'!$B$2:$B$135="Sleep & Neurology")+('Equipment Master List'!$B$2:$B$135="IV & Infusion")+('Equipment Master List'!$B$2:$B$135="Aesthetic & Regenerative")+('Equipment Master List'!$B$2:$B$135="Nutrition & GI Diagnostics")+('Equipment Master List'!$B$2:$B$135="Body Composition & Performance")+('Equipment Master List'!$B$2:$B$135="Telemedicine & Digital Health"))*IFERROR('Equipment Master List'!$N$2:$N$135+0,0)*IFERROR('Equipment Master List'!$J$2:$J$135+0,0)) -> 2577700 | D20: =SUMPRODUCT((((1*('Equipment Master List'!$G$2:$G$135="Six Senses Place-tier")+2*('Equipment Master List'!$G$2:$G$135="SHA/Chenot-tier")+3*('Equipment Master List'!$G$2:$G$135="Lanserhof/CLP-tier"))>0)*((1*('Equipment Master List'!$G$2:$G$135="Six Senses Place-tier")+2*('Equipment Master List'!$G$2:$G$135="SHA/Chenot-tier")+3*('Equipment Master List'!$G$2:$G$135="Lanserhof/CLP-tier"))<=1))*(('Equipment Master List'!$B$2:$B$135="Diagnostic Imaging")+('Equipment Master List'!$B$2:$B$135="Laboratory & Biomarkers")+('Equipment Master List'!$B$2:$B$135="Cardiology & Pulmonology")+('Equipment Master List'!$B$2:$B$135="Sleep & Neurology")+('Equipment Master List'!$B$2:$B$135="IV & Infusion")+('Equipment Master List'!$B$2:$B$135="Aesthetic & Regenerative")+('Equipment Master List'!$B$2:$B$135="Nutrition & GI Diagnostics")+('Equipment Master List'!$B$2:$B$135="Body Composition & Performance")+('Equipment Master List'!$B$2:$B$135="Telemedicine & Digital Health"))*IFERROR('Equipment Master List'!$N$2:$N$135+0,0)*IFERROR('Equipment Master List'!$J$2:$J$135+0,0)) -> 337200
A21: Total Spa & Recovery capex | B21: =SUMPRODUCT((((1*('Equipment Master List'!$G$2:$G$135="Six Senses Place-tier")+2*('Equipment Master List'!$G$2:$G$135="SHA/Chenot-tier")+3*('Equipment Master List'!$G$2:$G$135="Lanserhof/CLP-tier"))>0)*((1*('Equipment Master List'!$G$2:$G$135="Six Senses Place-tier")+2*('Equipment Master List'!$G$2:$G$135="SHA/Chenot-tier")+3*('Equipment Master List'!$G$2:$G$135="Lanserhof/CLP-tier"))<=3))*(('Equipment Master List'!$B$2:$B$135="Hydrotherapy & Spa")+('Equipment Master List'!$B$2:$B$135="Cryo & Thermal"))*IFERROR('Equipment Master List'!$N$2:$N$135+0,0)*IFERROR('Equipment Master List'!$J$2:$J$135+0,0)) -> 1945200 | C21: =SUMPRODUCT((((1*('Equipment Master List'!$G$2:$G$135="Six Senses Place-tier")+2*('Equipment Master List'!$G$2:$G$135="SHA/Chenot-tier")+3*('Equipment Master List'!$G$2:$G$135="Lanserhof/CLP-tier"))>0)*((1*('Equipment Master List'!$G$2:$G$135="Six Senses Place-tier")+2*('Equipment Master List'!$G$2:$G$135="SHA/Chenot-tier")+3*('Equipment Master List'!$G$2:$G$135="Lanserhof/CLP-tier"))<=2))*(('Equipment Master List'!$B$2:$B$135="Hydrotherapy & Spa")+('Equipment Master List'!$B$2:$B$135="Cryo & Thermal"))*IFERROR('Equipment Master List'!$N$2:$N$135+0,0)*IFERROR('Equipment Master List'!$J$2:$J$135+0,0)) -> 1945200 | D21: =SUMPRODUCT((((1*('Equipment Master List'!$G$2:$G$135="Six Senses Place-tier")+2*('Equipment Master List'!$G$2:$G$135="SHA/Chenot-tier")+3*('Equipment Master List'!$G$2:$G$135="Lanserhof/CLP-tier"))>0)*((1*('Equipment Master List'!$G$2:$G$135="Six Senses Place-tier")+2*('Equipment Master List'!$G$2:$G$135="SHA/Chenot-tier")+3*('Equipment Master List'!$G$2:$G$135="Lanserhof/CLP-tier"))<=1))*(('Equipment Master List'!$B$2:$B$135="Hydrotherapy & Spa")+('Equipment Master List'!$B$2:$B$135="Cryo & Thermal"))*IFERROR('Equipment Master List'!$N$2:$N$135+0,0)*IFERROR('Equipment Master List'!$J$2:$J$135+0,0)) -> 1945200
A22: Total Fitness & Movement capex | B22: =SUMPRODUCT((((1*('Equipment Master List'!$G$2:$G$135="Six Senses Place-tier")+2*('Equipment Master List'!$G$2:$G$135="SHA/Chenot-tier")+3*('Equipment Master List'!$G$2:$G$135="Lanserhof/CLP-tier"))>0)*((1*('Equipment Master List'!$G$2:$G$135="Six Senses Place-tier")+2*('Equipment Master List'!$G$2:$G$135="SHA/Chenot-tier")+3*('Equipment Master List'!$G$2:$G$135="Lanserhof/CLP-tier"))<=3))*(('Equipment Master List'!$B$2:$B$135="Movement & Rehab")+('Equipment Master List'!$B$2:$B$135="Gym & Strength"))*IFERROR('Equipment Master List'!$N$2:$N$135+0,0)*IFERROR('Equipment Master List'!$J$2:$J$135+0,0)) -> 1585000 | C22: =SUMPRODUCT((((1*('Equipment Master List'!$G$2:$G$135="Six Senses Place-tier")+2*('Equipment Master List'!$G$2:$G$135="SHA/Chenot-tier")+3*('Equipment Master List'!$G$2:$G$135="Lanserhof/CLP-tier"))>0)*((1*('Equipment Master List'!$G$2:$G$135="Six Senses Place-tier")+2*('Equipment Master List'!$G$2:$G$135="SHA/Chenot-tier")+3*('Equipment Master List'!$G$2:$G$135="Lanserhof/CLP-tier"))<=2))*(('Equipment Master List'!$B$2:$B$135="Movement & Rehab")+('Equipment Master List'!$B$2:$B$135="Gym & Strength"))*IFERROR('Equipment Master List'!$N$2:$N$135+0,0)*IFERROR('Equipment Master List'!$J$2:$J$135+0,0)) -> 687000 | D22: =SUMPRODUCT((((1*('Equipment Master List'!$G$2:$G$135="Six Senses Place-tier")+2*('Equipment Master List'!$G$2:$G$135="SHA/Chenot-tier")+3*('Equipment Master List'!$G$2:$G$135="Lanserhof/CLP-tier"))>0)*((1*('Equipment Master List'!$G$2:$G$135="Six Senses Place-tier")+2*('Equipment Master List'!$G$2:$G$135="SHA/Chenot-tier")+3*('Equipment Master List'!$G$2:$G$135="Lanserhof/CLP-tier"))<=1))*(('Equipment Master List'!$B$2:$B$135="Movement & Rehab")+('Equipment Master List'!$B$2:$B$135="Gym & Strength"))*IFERROR('Equipment Master List'!$N$2:$N$135+0,0)*IFERROR('Equipment Master List'!$J$2:$J$135+0,0)) -> 687000
A23: Total IT & Software capex (upfront) | B23: =SUMPRODUCT((((1*('Equipment Master List'!$G$2:$G$135="Six Senses Place-tier")+2*('Equipment Master List'!$G$2:$G$135="SHA/Chenot-tier")+3*('Equipment Master List'!$G$2:$G$135="Lanserhof/CLP-tier"))>0)*((1*('Equipment Master List'!$G$2:$G$135="Six Senses Place-tier")+2*('Equipment Master List'!$G$2:$G$135="SHA/Chenot-tier")+3*('Equipment Master List'!$G$2:$G$135="Lanserhof/CLP-tier"))<=3))*(('Equipment Master List'!$B$2:$B$135="IT, EHR, Patient Software"))*IFERROR('Equipment Master List'!$N$2:$N$135+0,0)*IFERROR('Equipment Master List'!$J$2:$J$135+0,0)) -> 1208000 | C23: =SUMPRODUCT((((1*('Equipment Master List'!$G$2:$G$135="Six Senses Place-tier")+2*('Equipment Master List'!$G$2:$G$135="SHA/Chenot-tier")+3*('Equipment Master List'!$G$2:$G$135="Lanserhof/CLP-tier"))>0)*((1*('Equipment Master List'!$G$2:$G$135="Six Senses Place-tier")+2*('Equipment Master List'!$G$2:$G$135="SHA/Chenot-tier")+3*('Equipment Master List'!$G$2:$G$135="Lanserhof/CLP-tier"))<=2))*(('Equipment Master List'!$B$2:$B$135="IT, EHR, Patient Software"))*IFERROR('Equipment Master List'!$N$2:$N$135+0,0)*IFERROR('Equipment Master List'!$J$2:$J$135+0,0)) -> 1208000 | D23: =SUMPRODUCT((((1*('Equipment Master List'!$G$2:$G$135="Six Senses Place-tier")+2*('Equipment Master List'!$G$2:$G$135="SHA/Chenot-tier")+3*('Equipment Master List'!$G$2:$G$135="Lanserhof/CLP-tier"))>0)*((1*('Equipment Master List'!$G$2:$G$135="Six Senses Place-tier")+2*('Equipment Master List'!$G$2:$G$135="SHA/Chenot-tier")+3*('Equipment Master List'!$G$2:$G$135="Lanserhof/CLP-tier"))<=1))*(('Equipment Master List'!$B$2:$B$135="IT, EHR, Patient Software"))*IFERROR('Equipment Master List'!$N$2:$N$135+0,0)*IFERROR('Equipment Master List'!$J$2:$J$135+0,0)) -> 988000
A24: Total Kitchen & F&B capex | B24: =SUMPRODUCT((((1*('Equipment Master List'!$G$2:$G$135="Six Senses Place-tier")+2*('Equipment Master List'!$G$2:$G$135="SHA/Chenot-tier")+3*('Equipment Master List'!$G$2:$G$135="Lanserhof/CLP-tier"))>0)*((1*('Equipment Master List'!$G$2:$G$135="Six Senses Place-tier")+2*('Equipment Master List'!$G$2:$G$135="SHA/Chenot-tier")+3*('Equipment Master List'!$G$2:$G$135="Lanserhof/CLP-tier"))<=3))*(('Equipment Master List'!$B$2:$B$135="Kitchen & F&B"))*IFERROR('Equipment Master List'!$N$2:$N$135+0,0)*IFERROR('Equipment Master List'!$J$2:$J$135+0,0)) -> 1243800 | C24: =SUMPRODUCT((((1*('Equipment Master List'!$G$2:$G$135="Six Senses Place-tier")+2*('Equipment Master List'!$G$2:$G$135="SHA/Chenot-tier")+3*('Equipment Master List'!$G$2:$G$135="Lanserhof/CLP-tier"))>0)*((1*('Equipment Master List'!$G$2:$G$135="Six Senses Place-tier")+2*('Equipment Master List'!$G$2:$G$135="SHA/Chenot-tier")+3*('Equipment Master List'!$G$2:$G$135="Lanserhof/CLP-tier"))<=2))*(('Equipment Master List'!$B$2:$B$135="Kitchen & F&B"))*IFERROR('Equipment Master List'!$N$2:$N$135+0,0)*IFERROR('Equipment Master List'!$J$2:$J$135+0,0)) -> 1243800 | D24: =SUMPRODUCT((((1*('Equipment Master List'!$G$2:$G$135="Six Senses Place-tier")+2*('Equipment Master List'!$G$2:$G$135="SHA/Chenot-tier")+3*('Equipment Master List'!$G$2:$G$135="Lanserhof/CLP-tier"))>0)*((1*('Equipment Master List'!$G$2:$G$135="Six Senses Place-tier")+2*('Equipment Master List'!$G$2:$G$135="SHA/Chenot-tier")+3*('Equipment Master List'!$G$2:$G$135="Lanserhof/CLP-tier"))<=1))*(('Equipment Master List'!$B$2:$B$135="Kitchen & F&B"))*IFERROR('Equipment Master List'!$N$2:$N$135+0,0)*IFERROR('Equipment Master List'!$J$2:$J$135+0,0)) -> 1243800
A25: Total Medical Infrastructure capex | B25: =SUMPRODUCT((((1*('Equipment Master List'!$G$2:$G$135="Six Senses Place-tier")+2*('Equipment Master List'!$G$2:$G$135="SHA/Chenot-tier")+3*('Equipment Master List'!$G$2:$G$135="Lanserhof/CLP-tier"))>0)*((1*('Equipment Master List'!$G$2:$G$135="Six Senses Place-tier")+2*('Equipment Master List'!$G$2:$G$135="SHA/Chenot-tier")+3*('Equipment Master List'!$G$2:$G$135="Lanserhof/CLP-tier"))<=3))*(('Equipment Master List'!$B$2:$B$135="Medical Infrastructure"))*IFERROR('Equipment Master List'!$N$2:$N$135+0,0)*IFERROR('Equipment Master List'!$J$2:$J$135+0,0)) -> 1295000 | C25: =SUMPRODUCT((((1*('Equipment Master List'!$G$2:$G$135="Six Senses Place-tier")+2*('Equipment Master List'!$G$2:$G$135="SHA/Chenot-tier")+3*('Equipment Master List'!$G$2:$G$135="Lanserhof/CLP-tier"))>0)*((1*('Equipment Master List'!$G$2:$G$135="Six Senses Place-tier")+2*('Equipment Master List'!$G$2:$G$135="SHA/Chenot-tier")+3*('Equipment Master List'!$G$2:$G$135="Lanserhof/CLP-tier"))<=2))*(('Equipment Master List'!$B$2:$B$135="Medical Infrastructure"))*IFERROR('Equipment Master List'!$N$2:$N$135+0,0)*IFERROR('Equipment Master List'!$J$2:$J$135+0,0)) -> 155000 | D25: =SUMPRODUCT((((1*('Equipment Master List'!$G$2:$G$135="Six Senses Place-tier")+2*('Equipment Master List'!$G$2:$G$135="SHA/Chenot-tier")+3*('Equipment Master List'!$G$2:$G$135="Lanserhof/CLP-tier"))>0)*((1*('Equipment Master List'!$G$2:$G$135="Six Senses Place-tier")+2*('Equipment Master List'!$G$2:$G$135="SHA/Chenot-tier")+3*('Equipment Master List'!$G$2:$G$135="Lanserhof/CLP-tier"))<=1))*(('Equipment Master List'!$B$2:$B$135="Medical Infrastructure"))*IFERROR('Equipment Master List'!$N$2:$N$135+0,0)*IFERROR('Equipment Master List'!$J$2:$J$135+0,0)) -> 0
A26: TOTAL CAPEX | B26: =SUM(B20:B25) -> 16015700 | C26: =SUM(C20:C25) -> 7816700 | D26: =SUM(D20:D25) -> 5201200
A27: Capex per key | B27: =B26/$B$3 -> 177952.22 | C27: =C26/$B$3 -> 86852.222 | D27: =D26/$B$3 -> 57791.111
A29: REGION — Asia ($)
A30: Group | B30: Lanserhof/CLP-tier | C30: SHA/Chenot-tier | D30: Six Senses Place-tier
A31: Total Medical capex | B31: =SUMPRODUCT((((1*('Equipment Master List'!$G$2:$G$135="Six Senses Place-tier")+2*('Equipment Master List'!$G$2:$G$135="SHA/Chenot-tier")+3*('Equipment Master List'!$G$2:$G$135="Lanserhof/CLP-tier"))>0)*((1*('Equipment Master List'!$G$2:$G$135="Six Senses Place-tier")+2*('Equipment Master List'!$G$2:$G$135="SHA/Chenot-tier")+3*('Equipment Master List'!$G$2:$G$135="Lanserhof/CLP-tier"))<=3))*(('Equipment Master List'!$B$2:$B$135="Diagnostic Imaging")+('Equipment Master List'!$B$2:$B$135="Laboratory & Biomarkers")+('Equipment Master List'!$B$2:$B$135="Cardiology & Pulmonology")+('Equipment Master List'!$B$2:$B$135="Sleep & Neurology")+('Equipment Master List'!$B$2:$B$135="IV & Infusion")+('Equipment Master List'!$B$2:$B$135="Aesthetic & Regenerative")+('Equipment Master List'!$B$2:$B$135="Nutrition & GI Diagnostics")+('Equipment Master List'!$B$2:$B$135="Body Composition & Performance")+('Equipment Master List'!$B$2:$B$135="Telemedicine & Digital Health"))*IFERROR('Equipment Master List'!$N$2:$N$135+0,0)*IFERROR('Equipment Master List'!$K$2:$K$135+0,0)) -> 6556200 | C31: =SUMPRODUCT((((1*('Equipment Master List'!$G$2:$G$135="Six Senses Place-tier")+2*('Equipment Master List'!$G$2:$G$135="SHA/Chenot-tier")+3*('Equipment Master List'!$G$2:$G$135="Lanserhof/CLP-tier"))>0)*((1*('Equipment Master List'!$G$2:$G$135="Six Senses Place-tier")+2*('Equipment Master List'!$G$2:$G$135="SHA/Chenot-tier")+3*('Equipment Master List'!$G$2:$G$135="Lanserhof/CLP-tier"))<=2))*(('Equipment Master List'!$B$2:$B$135="Diagnostic Imaging")+('Equipment Master List'!$B$2:$B$135="Laboratory & Biomarkers")+('Equipment Master List'!$B$2:$B$135="Cardiology & Pulmonology")+('Equipment Master List'!$B$2:$B$135="Sleep & Neurology")+('Equipment Master List'!$B$2:$B$135="IV & Infusion")+('Equipment Master List'!$B$2:$B$135="Aesthetic & Regenerative")+('Equipment Master List'!$B$2:$B$135="Nutrition & GI Diagnostics")+('Equipment Master List'!$B$2:$B$135="Body Composition & Performance")+('Equipment Master List'!$B$2:$B$135="Telemedicine & Digital Health"))*IFERROR('Equipment Master List'!$N$2:$N$135+0,0)*IFERROR('Equipment Master List'!$K$2:$K$135+0,0)) -> 1883200 | D31: =SUMPRODUCT((((1*('Equipment Master List'!$G$2:$G$135="Six Senses Place-tier")+2*('Equipment Master List'!$G$2:$G$135="SHA/Chenot-tier")+3*('Equipment Master List'!$G$2:$G$135="Lanserhof/CLP-tier"))>0)*((1*('Equipment Master List'!$G$2:$G$135="Six Senses Place-tier")+2*('Equipment Master List'!$G$2:$G$135="SHA/Chenot-tier")+3*('Equipment Master List'!$G$2:$G$135="Lanserhof/CLP-tier"))<=1))*(('Equipment Master List'!$B$2:$B$135="Diagnostic Imaging")+('Equipment Master List'!$B$2:$B$135="Laboratory & Biomarkers")+('Equipment Master List'!$B$2:$B$135="Cardiology & Pulmonology")+('Equipment Master List'!$B$2:$B$135="Sleep & Neurology")+('Equipment Master List'!$B$2:$B$135="IV & Infusion")+('Equipment Master List'!$B$2:$B$135="Aesthetic & Regenerative")+('Equipment Master List'!$B$2:$B$135="Nutrition & GI Diagnostics")+('Equipment Master List'!$B$2:$B$135="Body Composition & Performance")+('Equipment Master List'!$B$2:$B$135="Telemedicine & Digital Health"))*IFERROR('Equipment Master List'!$N$2:$N$135+0,0)*IFERROR('Equipment Master List'!$K$2:$K$135+0,0)) -> 247000
A32: Total Spa & Recovery capex | B32: =SUMPRODUCT((((1*('Equipment Master List'!$G$2:$G$135="Six Senses Place-tier")+2*('Equipment Master List'!$G$2:$G$135="SHA/Chenot-tier")+3*('Equipment Master List'!$G$2:$G$135="Lanserhof/CLP-tier"))>0)*((1*('Equipment Master List'!$G$2:$G$135="Six Senses Place-tier")+2*('Equipment Master List'!$G$2:$G$135="SHA/Chenot-tier")+3*('Equipment Master List'!$G$2:$G$135="Lanserhof/CLP-tier"))<=3))*(('Equipment Master List'!$B$2:$B$135="Hydrotherapy & Spa")+('Equipment Master List'!$B$2:$B$135="Cryo & Thermal"))*IFERROR('Equipment Master List'!$N$2:$N$135+0,0)*IFERROR('Equipment Master List'!$K$2:$K$135+0,0)) -> 1528800 | C32: =SUMPRODUCT((((1*('Equipment Master List'!$G$2:$G$135="Six Senses Place-tier")+2*('Equipment Master List'!$G$2:$G$135="SHA/Chenot-tier")+3*('Equipment Master List'!$G$2:$G$135="Lanserhof/CLP-tier"))>0)*((1*('Equipment Master List'!$G$2:$G$135="Six Senses Place-tier")+2*('Equipment Master List'!$G$2:$G$135="SHA/Chenot-tier")+3*('Equipment Master List'!$G$2:$G$135="Lanserhof/CLP-tier"))<=2))*(('Equipment Master List'!$B$2:$B$135="Hydrotherapy & Spa")+('Equipment Master List'!$B$2:$B$135="Cryo & Thermal"))*IFERROR('Equipment Master List'!$N$2:$N$135+0,0)*IFERROR('Equipment Master List'!$K$2:$K$135+0,0)) -> 1528800 | D32: =SUMPRODUCT((((1*('Equipment Master List'!$G$2:$G$135="Six Senses Place-tier")+2*('Equipment Master List'!$G$2:$G$135="SHA/Chenot-tier")+3*('Equipment Master List'!$G$2:$G$135="Lanserhof/CLP-tier"))>0)*((1*('Equipment Master List'!$G$2:$G$135="Six Senses Place-tier")+2*('Equipment Master List'!$G$2:$G$135="SHA/Chenot-tier")+3*('Equipment Master List'!$G$2:$G$135="Lanserhof/CLP-tier"))<=1))*(('Equipment Master List'!$B$2:$B$135="Hydrotherapy & Spa")+('Equipment Master List'!$B$2:$B$135="Cryo & Thermal"))*IFERROR('Equipment Master List'!$N$2:$N$135+0,0)*IFERROR('Equipment Master List'!$K$2:$K$135+0,0)) -> 1528800
